Workbook

Sheet top-20-selection
A1: Rank | B1: Page URL | C1: Intent Pts | D1: Traffic Pts | E1: PageType Pts | F1: Engage Pts | G1: Weighted Score | H1: Sessions | I1: Page Type | J1: Bounce Rate | K1: Avg Engage Time | L1: Scroll Depth % | M1: Placement | N1: Click Hot Zones | O1: Impl Type | P1: Status | Q1: URL | S1: Click Hot Zone References (Column R)
A2: 1 | B2: /client-solutions/ | C2: 35 | D2: 24 | E2: 20 | F2: 15 | G2: =sum(C2:F2) -> 94 | H2: 249 | I2: Service | J2: 0.18 | K2: 39.2s | L2: 0.5583 | M2: UPPER MID | N2: nav menu | O2: =IF(AND(I2="Service", H2>100), "Banner", IF(OR(N2="nav menu", N2="nav CTA", N2="nav phone"), "Button", IF(OR(N2="below-fold", N2="trust carousel", N2="hero CTA", N2="hero image"), "Button", IF(OR(N2="hero headline", N2="hero text"), "Button", IF(OR(N2="text block", N2="headings"), "Anchor Link", IF(OR(I2="Industry", I2="Case Study"), "Button", IF(OR(N2="none", N2=""), "Banner", "Button"))))))) -> Banner | P2: TRUE | Q2: https://salesxceleration.com/client-solutions/ | S2: Priority | T2: Click Hot Zone | U2: Write | V2: What It Means | W2: Where to Place
A3: 2 | B3: /state-of-sales/ | C3: 35 | D3: 30 | E3: 20 | F3: 5 | G3: =sum(C3:F3) -> 90 | H3: 308 | I3: Service | J3: 0.73 | K3: 3.5s | L3: 0.4208 | M3: TOP | N3: nav menu | O3: =IF(AND(I3="Service", H3>100), "Banner", IF(OR(N3="nav menu", N3="nav CTA", N3="nav phone"), "Button", IF(OR(N3="below-fold", N3="trust carousel", N3="hero CTA", N3="hero image"), "Button", IF(OR(N3="hero headline", N3="hero text"), "Button", IF(OR(N3="text block", N3="headings"), "Anchor Link", IF(OR(I3="Industry", I3="Case Study"), "Button", IF(OR(N3="none", N3=""), "Banner", "Button"))))))) -> Banner | P3: TRUE | Q3: https://salesxceleration.com/state-of-sales/ | S3: 1 | T3: Service + >100 sessions | U3: (any) | V3: High-traffic flagship page | W3: Banner in upper-mid
A4: 3 | B4: /sales-strategy/ | C4: 35 | D4: 8 | E4: 20 | F4: 15 | G4: =sum(C4:F4) -> 78 | H4: 83 | I4: Service | J4: 0.18 | K4: 76.5s | L4: 0.5897 | M4: UPPER MID | N4: nav menu | O4: =IF(AND(I4="Service", H4>100), "Banner", IF(OR(N4="nav menu", N4="nav CTA", N4="nav phone"), "Button", IF(OR(N4="below-fold", N4="trust carousel", N4="hero CTA", N4="hero image"), "Button", IF(OR(N4="hero headline", N4="hero text"), "Button", IF(OR(N4="text block", N4="headings"), "Anchor Link", IF(OR(I4="Industry", I4="Case Study"), "Button", IF(OR(N4="none", N4=""), "Banner", "Button"))))))) -> Button | P4: TRUE | Q4: https://salesxceleration.com/sales-strategy/ | S4: 2 | T4: Nav menu/CTA/phone clicks | U4: nav menu / nav CTA / nav phone | V4: Users engaging with header | W4: Button in hero or next section
A5: 4 | B5: /private-equity-solutions/ | C5: 35 | D5: 5 | E5: 20 | F5: 15 | G5: =sum(C5:F5) -> 75 | H5: 47 | I5: Service | J5: 0.15 | K5: 86.2s | L5: 0.589 | M5: UPPER MID | N5: trust carousel | O5: =IF(AND(I5="Service", H5>100), "Banner", IF(OR(N5="nav menu", N5="nav CTA", N5="nav phone"), "Button", IF(OR(N5="below-fold", N5="trust carousel", N5="hero CTA", N5="hero image"), "Button", IF(OR(N5="hero headline", N5="hero text"), "Button", IF(OR(N5="text block", N5="headings"), "Anchor Link", IF(OR(I5="Industry", I5="Case Study"), "Button", IF(OR(N5="none", N5=""), "Banner", "Button"))))))) -> Button | P5: TRUE | Q5: https://salesxceleration.com/private-equity-solutions/ | S5: 3 | T5: Below-fold text, CTA or carousel | U5: below-fold / trust carousel | V5: Users scrolling and engaging | W5: Button BEFORE or AFTER hot zone
A6: 5 | B6: /private-equity-solutions/tech-mfg-case-study/ | C6: 35 | D6: 9 | E6: 15 | F6: 15 | G6: =sum(C6:F6) -> 74 | H6: 89 | I6: Case Study | J6: 0.43 | K6: 126.4s | L6: 0.5793 | M6: UPPER MID | N6: hero headline | O6: =IF(AND(I6="Service", H6>100), "Banner", IF(OR(N6="nav menu", N6="nav CTA", N6="nav phone"), "Button", IF(OR(N6="below-fold", N6="trust carousel", N6="hero CTA", N6="hero image"), "Button", IF(OR(N6="hero headline", N6="hero text"), "Button", IF(OR(N6="text block", N6="headings"), "Anchor Link", IF(OR(I6="Industry", I6="Case Study"), "Button", IF(OR(N6="none", N6=""), "Banner", "Button"))))))) -> Button | P6: TRUE | Q6: https://salesxceleration.com/private-equity-solutions/tech-mfg-case-study/ | S6: 4 | T6: Hero element clicks | U6: hero CTA / hero headline / hero text / hero image | V6: Users engaging with hero | W6: Button in hero (secondary) or below
A7: 6 | B7: /sales-infrastructure/ | C7: 35 | D7: 4 | E7: 20 | F7: 15 | G7: =sum(C7:F7) -> 74 | H7: 42 | I7: Service | J7: 0.29 | K7: 49.5s | L7: 0.5774 | M7: UPPER MID | N7: nav menu | O7: =IF(AND(I7="Service", H7>100), "Banner", IF(OR(N7="nav menu", N7="nav CTA", N7="nav phone"), "Button", IF(OR(N7="below-fold", N7="trust carousel", N7="hero CTA", N7="hero image"), "Button", IF(OR(N7="hero headline", N7="hero text"), "Button", IF(OR(N7="text block", N7="headings"), "Anchor Link", IF(OR(I7="Industry", I7="Case Study"), "Button", IF(OR(N7="none", N7=""), "Banner", "Button"))))))) -> Button | P7: TRUE | Q7: https://salesxceleration.com/sales-infrastructure/ | S7: 5 | T7: Text paragraphs | U7: text block | V7: Users treating text as clickable | W7: Anchor Link within text
A8: 7 | B8: /sales-team/ | C8: 35 | D8: 5 | E8: 20 | F8: 12 | G8: =sum(C8:F8) -> 72 | H8: 50 | I8: Service | J8: 0.12 | K8: 18.0s | L8: 0.5824 | M8: UPPER MID | N8: nav menu | O8: =IF(AND(I8="Service", H8>100), "Banner", IF(OR(N8="nav menu", N8="nav CTA", N8="nav phone"), "Button", IF(OR(N8="below-fold", N8="trust carousel", N8="hero CTA", N8="hero image"), "Button", IF(OR(N8="hero headline", N8="hero text"), "Button", IF(OR(N8="text block", N8="headings"), "Anchor Link", IF(OR(I8="Industry", I8="Case Study"), "Button", IF(OR(N8="none", N8=""), "Banner", "Button"))))))) -> Button | P8: TRUE | Q8: https://salesxceleration.com/sales-team/ | S8: 5 | T8: Headings | U8: headings | V8: Users trying to navigate | W8: Anchor Link in section
A9: 8 | B9: /private-equity-solutions/private-equity/ | C9: 35 | D9: 6 | E9: 20 | F9: 10 | G9: =sum(C9:F9) -> 71 | H9: 57 | I9: Service | J9: 0.46 | K9: 22.9s | L9: 0.5958 | M9: UPPER MID | N9: nav menu | O9: =IF(AND(I9="Service", H9>100), "Banner", IF(OR(N9="nav menu", N9="nav CTA", N9="nav phone"), "Button", IF(OR(N9="below-fold", N9="trust carousel", N9="hero CTA", N9="hero image"), "Button", IF(OR(N9="hero headline", N9="hero text"), "Button", IF(OR(N9="text block", N9="headings"), "Anchor Link", IF(OR(I9="Industry", I9="Case Study"), "Button", IF(OR(N9="none", N9=""), "Banner", "Button"))))))) -> Button | P9: TRUE | Q9: https://salesxceleration.com/private-equity-solutions/private-equity/ | S9: 6 | T9: Industry or Case Study page | U9: (any) | V9: Page type default | W9: Button after key section
A10: 9 | B10: /private-equity-solutions/portfolio-company/ | C10: 35 | D10: 4 | E10: 20 | F10: 12 | G10: =sum(C10:F10) -> 71 | H10: 46 | I10: Service | J10: 0.3 | K10: 15.2s | L10: 0.6264 | M10: MID | N10: nav menu | O10: =IF(AND(I10="Service", H10>100), "Banner", IF(OR(N10="nav menu", N10="nav CTA", N10="nav phone"), "Button", IF(OR(N10="below-fold", N10="trust carousel", N10="hero CTA", N10="hero image"), "Button", IF(OR(N10="hero headline", N10="hero text"), "Button", IF(OR(N10="text block", N10="headings"), "Anchor Link", IF(OR(I10="Industry", I10="Case Study"), "Button", IF(OR(N10="none", N10=""), "Banner", "Button"))))))) -> Button | P10: TRUE | Q10: https://salesxceleration.com/private-equity-solutions/portfolio-company/ | S10: 7 | T10: Image clicks | U10: images | V10: Users expect interaction | W10: Button below image
A11: 10 | B11: /industries/technology/ | C11: 35 | D11: 3 | E11: 18 | F11: 15 | G11: =sum(C11:F11) -> 71 | H11: 32 | I11: Industry | J11: 0.38 | K11: 55.6s | L11: 0.6226 | M11: MID | N11: below-fold | O11: =IF(AND(I11="Service", H11>100), "Banner", IF(OR(N11="nav menu", N11="nav CTA", N11="nav phone"), "Button", IF(OR(N11="below-fold", N11="trust carousel", N11="hero CTA", N11="hero image"), "Button", IF(OR(N11="hero headline", N11="hero text"), "Button", IF(OR(N11="text block", N11="headings"), "Anchor Link", IF(OR(I11="Industry", I11="Case Study"), "Button", IF(OR(N11="none", N11=""), "Banner", "Button"))))))) -> Button | P11: TRUE | Q11: https://salesxceleration.com/industries/technology/ | S11: 8 | T11: No clear pattern | U11: none | V11: Need to create attention | W11: Banner in upper-mid
A12: 11 | B12: /sales-management/ | C12: 35 | D12: 4 | E12: 20 | F12: 10 | G12: =sum(C12:F12) -> 69 | H12: 41 | I12: Service | J12: 0.44 | K12: 23.6s | L12: 0.5675 | M12: UPPER MID | N12: nav menu | O12: =IF(AND(I12="Service", H12>100), "Banner", IF(OR(N12="nav menu", N12="nav CTA", N12="nav phone"), "Button", IF(OR(N12="below-fold", N12="trust carousel", N12="hero CTA", N12="hero image"), "Button", IF(OR(N12="hero headline", N12="hero text"), "Button", IF(OR(N12="text block", N12="headings"), "Anchor Link", IF(OR(I12="Industry", I12="Case Study"), "Button", IF(OR(N12="none", N12=""), "Banner", "Button"))))))) -> Button | P12: TRUE | Q12: https://salesxceleration.com/sales-management/
A13: 12 | B13: /private-equity-solutions/healthcare-managed-services-case-study/ | C13: 35 | D13: 6 | E13: 15 | F13: 12 | G13: =sum(C13:F13) -> 68 | H13: 62 | I13: Case Study | J13: 0.34 | K13: 27.0s | L13: 0.4671 | M13: TOP | N13: below-fold | O13: =IF(AND(I13="Service", H13>100), "Banner", IF(OR(N13="nav menu", N13="nav CTA", N13="nav phone"), "Button", IF(OR(N13="below-fold", N13="trust carousel", N13="hero CTA", N13="hero image"), "Button", IF(OR(N13="hero headline", N13="hero text"), "Button", IF(OR(N13="text block", N13="headings"), "Anchor Link", IF(OR(I13="Industry", I13="Case Study"), "Button", IF(OR(N13="none", N13=""), "Banner", "Button"))))))) -> Button | P13: TRUE | Q13: https://salesxceleration.com/private-equity-solutions/healthcare-managed-services-case-study/
A14: 13 | B14: /industries/franchises/ | C14: 35 | D14: 1 | E14: 18 | F14: 12 | G14: =sum(C14:F14) -> 66 | H14: 12 | I14: Industry | J14: 0.17 | K14: 21.5s | L14: 0.622 | M14: MID | N14: nav menu | O14: =IF(AND(I14="Service", H14>100), "Banner", IF(OR(N14="nav menu", N14="nav CTA", N14="nav phone"), "Button", IF(OR(N14="below-fold", N14="trust carousel", N14="hero CTA", N14="hero image"), "Button", IF(OR(N14="hero headline", N14="hero text"), "Button", IF(OR(N14="text block", N14="headings"), "Anchor Link", IF(OR(I14="Industry", I14="Case Study"), "Button", IF(OR(N14="none", N14=""), "Banner", "Button"))))))) -> Button | P14: TRUE | Q14: https://salesxceleration.com/industries/franchises/
A15: 14 | B15: /industries/professional-services/ | C15: 35 | D15: 2 | E15: 18 | F15: 10 | G15: =sum(C15:F15) -> 65 | H15: 25 | I15: Industry | J15: 0.56 | K15: 26.7s | L15: 0.5754 | M15: UPPER MID | N15: below-fold | O15: =IF(AND(I15="Service", H15>100), "Banner", IF(OR(N15="nav menu", N15="nav CTA", N15="nav phone"), "Button", IF(OR(N15="below-fold", N15="trust carousel", N15="hero CTA", N15="hero image"), "Button", IF(OR(N15="hero headline", N15="hero text"), "Button", IF(OR(N15="text block", N15="headings"), "Anchor Link", IF(OR(I15="Industry", I15="Case Study"), "Button", IF(OR(N15="none", N15=""), "Banner", "Button"))))))) -> Button | P15: TRUE | Q15: https://salesxceleration.com/industries/professional-services/
A16: 15 | B16: /industries/manufacturing/ | C16: 35 | D16: 2 | E16: 18 | F16: 10 | G16: =sum(C16:F16) -> 65 | H16: 24 | I16: Industry | J16: 0.42 | K16: 18.6s | L16: 0.6054 | M16: MID | N16: below-fold | O16: =IF(AND(I16="Service", H16>100), "Banner", IF(OR(N16="nav menu", N16="nav CTA", N16="nav phone"), "Button", IF(OR(N16="below-fold", N16="trust carousel", N16="hero CTA", N16="hero image"), "Button", IF(OR(N16="hero headline", N16="hero text"), "Button", IF(OR(N16="text block", N16="headings"), "Anchor Link", IF(OR(I16="Industry", I16="Case Study"), "Button", IF(OR(N16="none", N16=""), "Banner", "Button"))))))) -> Button | P16: TRUE | Q16: https://salesxceleration.com/industries/manufacturing/
A17: 16 | B17: /industries/financial-services/ | C17: 35 | D17: 1 | E17: 18 | F17: 10 | G17: =sum(C17:F17) -> 64 | H17: 9 | I17: Industry | J17: 0.44 | K17: 14.1s | L17: 0.5181 | M17: UPPER MID | N17: nav menu | O17: =IF(AND(I17="Service", H17>100), "Banner", IF(OR(N17="nav menu", N17="nav CTA", N17="nav phone"), "Button", IF(OR(N17="below-fold", N17="trust carousel", N17="hero CTA", N17="hero image"), "Button", IF(OR(N17="hero headline", N17="hero text"), "Button", IF(OR(N17="text block", N17="headings"), "Anchor Link", IF(OR(I17="Industry", I17="Case Study"), "Button", IF(OR(N17="none", N17=""), "Banner", "Button"))))))) -> Button | P17: TRUE | Q17: https://salesxceleration.com/industries/financial-services/
A18: 17 | B18: /industries/legal/ | C18: 35 | D18: 1 | E18: 18 | F18: 5 | G18: =sum(C18:F18) -> 59 | H18: 9 | I18: Industry | J18: 0.67 | K18: 4.3s | L18: 0.462 | M18: TOP | N18: below-fold | O18: =IF(AND(I18="Service", H18>100), "Banner", IF(OR(N18="nav menu", N18="nav CTA", N18="nav phone"), "Button", IF(OR(N18="below-fold", N18="trust carousel", N18="hero CTA", N18="hero image"), "Button", IF(OR(N18="hero headline", N18="hero text"), "Button", IF(OR(N18="text block", N18="headings"), "Anchor Link", IF(OR(I18="Industry", I18="Case Study"), "Button", IF(OR(N18="none", N18=""), "Banner", "Button"))))))) -> Button | P18: TRUE | Q18: https://salesxceleration.com/industries/legal/
A19: 18 | B19: /industries/private-equity/ | C19: 35 | D19: 0 | E19: 18 | F19: 5 | G19: =sum(C19:F19) -> 58 | H19: 5 | I19: Industry | J19: 0.8 | K19: 5.0s | L19: 0.5664 | M19: UPPER MID | N19: below-fold | O19: =IF(AND(I19="Service", H19>100), "Banner", IF(OR(N19="nav menu", N19="nav CTA", N19="nav phone"), "Button", IF(OR(N19="below-fold", N19="trust carousel", N19="hero CTA", N19="hero image"), "Button", IF(OR(N19="hero headline", N19="hero text"), "Button", IF(OR(N19="text block", N19="headings"), "Anchor Link", IF(OR(I19="Industry", I19="Case Study"), "Button", IF(OR(N19="none", N19=""), "Banner", "Button"))))))) -> Button | P19: TRUE | Q19: https://salesxceleration.com/industries/private-equity/
A20: 19 | B20: /case-study/electrical-manufacturing-sales-strategy-and-processes-provide-immediate-growth/ | C20: 35 | D20: 1 | E20: 15 | F20: 5 | G20: =sum(C20:F20) -> 56 | H20: 15 | I20: Case Study | J20: 0.73 | K20: 13.3s | L20: 0.6136 | M20: MID | N20: nav menu | O20: =IF(AND(I20="Service", H20>100), "Banner", IF(OR(N20="nav menu", N20="nav CTA", N20="nav phone"), "Button", IF(OR(N20="below-fold", N20="trust carousel", N20="hero CTA", N20="hero image"), "Button", IF(OR(N20="hero headline", N20="hero text"), "Button", IF(OR(N20="text block", N20="headings"), "Anchor Link", IF(OR(I20="Industry", I20="Case Study"), "Button", IF(OR(N20="none", N20=""), "Banner", "Button"))))))) -> Button | P20: TRUE | Q20: https://salesxceleration.com/case-study/electrical-manufacturing-sales-strategy-and-processes-provide-immediate-growth/
A21: 20 | B21: /ai-for-sales/ | C21: 20 | D21: 3 | E21: 20 | F21: 12 | G21: =sum(C21:F21) -> 55 | H21: 35 | I21: Service | J21: 0.2 | K21: 22.9s | L21: 0.5609 | M21: UPPER MID | N21: below-fold | O21: =IF(AND(I21="Service", H21>100), "Banner", IF(OR(N21="nav menu", N21="nav CTA", N21="nav phone"), "Button", IF(OR(N21="below-fold", N21="trust carousel", N21="hero CTA", N21="hero image"), "Button", IF(OR(N21="hero headline", N21="hero text"), "Button", IF(OR(N21="text block", N21="headings"), "Anchor Link", IF(OR(I21="Industry", I21="Case Study"), "Button", IF(OR(N21="none", N21=""), "Banner", "Button"))))))) -> Button | P21: TRUE | Q21: https://salesxceleration.com/ai-for-sales/
C23: Weighted Score = "Does the page match sales challenges?" + "Does it get traffic?" + "Is it a service page?" + "Do visitors engage?" | M23: Placement Decision (based on scroll depth) | N23: Why?
M24: < 50% → HERO (must be in top 20%) | N24: More than half of users leave before scrolling. If the CTA isn't in the hero, most users will never see it. Maximize visibility for the majority.
C25: --- INTENT SCORING BASED ON H1/H2/H2-2 --- | M25: 50-60% → UPPER-MID after intro paragraph (top 25-30% of page) ← 55.8% falls here | N25: Users ARE scrolling past the intro, but 40-50% still drop off before mid-page. Place CTA just after the intro so engaged users see it early, while not wasting hero space.
M26: > 60% → MID-PAGE OK (40-60% of page) | N26: Majority of users scroll deep on this page. Placing CTA mid-page catches users when they're most engaged with content—after they've read enough to be convinced.
C27: Intent Level | D27: Score | E27: H1/H2 Keywords Required
C28: HIGH | D28: 35 pts | E28: Contains: Sales Strategy, Sales Management, Sales Leadership, Sales Infrastructure, Revenue Growth, Fractional Sales, Sales Challenges, Sales Success, Sales Performance, Private Equity Solutions
C29: MED | D29: 20 pts | E29: Contains: AI for Sales, Sales Tips, Sales Tools, General Sales Topics
C30: LOW | D30: 10 pts | E30: Contains: Non-sales topics, motivational content, general business
C32: --- SCORE COMPONENT DEFINITIONS ---
C34: Component | D34: Max Pts | E34: Calculation
C35: Intent Pts | D35: 35 | E35: Based on H1, H2-1, H2-2 keyword analysis
C36: Traffic Pts | D36: 30 | E36: (Sessions ÷ 308) × 30 [rounded]
C37: PageType Pts | D37: 20 | E37: Service=20 | Industry=18 | Case Study=15
C38: Engage Pts | D38: 15 | E38: Excellent=15 (bounce<35% + engage>30s) | Good=12 (bounce<50% + engage>15s) | Medium=10 | Low=5

Sheet analytics
A1: Page path and screen class | B1: Character Count | C1: Sessions | D1: Key events | E1: Total users | F1: Bounce rate | G1: New users | H1: Engaged sessions | I1: Views | J1: Active users | K1: Average engagement time per active user | L1: H1 | M1: H2-1 | N1: H2-2
A2: /state-of-sales/ | B2: =len(A2) -> 16 | C2: 308 | D2: 0 | E2: 300 | F2: 0.73376623 | G2: 266 | H2: 82 | I2: 309 | J2: 297 | K2: 3.5151515 | L2: =vlookup(A2,salesx_all!B:E,2,0) -> 2025 State of Sales | Small to Mid-Size Businesses | M2: =vlookup(A2,salesx_all!B:D,3,0) -> The State of Sales: Crafting High-Performing Sales Organizations | N2: =vlookup(A2,salesx_all!B:E,4,0) -> Sales Strategy
A3: /client-solutions/ | B3: =len(A3) -> 18 | C3: 249 | D3: 2 | E3: 206 | F3: 0.17670683 | G3: 28 | H3: 205 | I3: 269 | J3: 203 | K3: 39.221675 | L3: =vlookup(A3,salesx_all!B:E,2,0) -> Tailored Sales Solutions for Your Business | M3: =vlookup(A3,salesx_all!B:D,3,0) -> Fractional Sales Leader: Your Source for Sales Success | N3: =vlookup(A3,salesx_all!B:E,4,0) -> Certified Sales Operating Management SystemTM
A4: /contact-us/ | B4: =len(A4) -> 12 | C4: 153 | D4: 0 | E4: 152 | F4: 0.24836601 | G4: 50 | H4: 115 | I4: 205 | J4: 152 | K4: 24.026316 | L4: =vlookup(A4,salesx_all!B:E,2,0) -> Contact Us | M4: =vlookup(A4,salesx_all!B:D,3,0) | N4: =vlookup(A4,salesx_all!B:E,4,0)
A5: /podcasts/ | B5: =len(A5) -> 10 | C5: 126 | D5: 0 | E5: 114 | F5: 0.25396825 | G5: 58 | H5: 94 | I5: 121 | J5: 113 | K5: 21.141593 | L5: =vlookup(A5,salesx_all!B:E,2,0) -> Sales Against The Odds | M5: =vlookup(A5,salesx_all!B:D,3,0) -> Latest Episode | N5: =vlookup(A5,salesx_all!B:E,4,0) -> Episode Library
A6: /free-sales-resources/ | B6: =len(A6) -> 22 | C6: 95 | D6: 0 | E6: 75 | F6: 0.58947368 | G6: 43 | H6: 39 | I6: 135 | J6: 74 | K6: 51.662162 | L6: =vlookup(A6,salesx_all!B:E,2,0) -> Free Sales Tools and Resources | M6: =vlookup(A6,salesx_all!B:D,3,0) -> Not sure where to start? Here are our top picks: | N6: =vlookup(A6,salesx_all!B:E,4,0) -> The AI Security Playbook: 6 Essentials Every Sales Organization Needs
A7: /case-studies/ | B7: =len(A7) -> 14 | C7: 92 | D7: 0 | E7: 87 | F7: 0.52173913 | G7: 58 | H7: 44 | I7: 102 | J7: 86 | K7: 18.802326 | L7: =vlookup(A7,salesx_all!B:E,2,0) -> Sales Success Stories and Case Studies | M7: =vlookup(A7,salesx_all!B:D,3,0) -> Featured Case Studies | N7: =vlookup(A7,salesx_all!B:E,4,0)
A8: /private-equity-solutions/tech-mfg-case-study/ | B8: =len(A8) -> 46 | C8: 89 | D8: 0 | E8: 50 | F8: 0.42696629 | G8: 44 | H8: 51 | I8: 98 | J8: 49 | K8: 126.38776 | L8: =vlookup(A8,salesx_all!B:E,2,0) -> Investment Profile and Challenges | M8: =vlookup(A8,salesx_all!B:D,3,0) -> $5M Turnaround: Inside Sales Xceleration's Sales Growth Strategy | N8: =vlookup(A8,salesx_all!B:E,4,0) -> Portfolio Company Challenges
A9: /sales-strategy/ | B9: =len(A9) -> 16 | C9: 83 | D9: 0 | E9: 70 | F9: 0.18072289 | G9: 7 | H9: 68 | I9: 87 | J9: 70 | K9: 76.528571 | L9: =vlookup(A9,salesx_all!B:E,2,0) -> Sales Strategy Consulting Services | M9: =vlookup(A9,salesx_all!B:D,3,0) -> Transform Your Sales with Proven Expertise | N9: =vlookup(A9,salesx_all!B:E,4,0) -> Build Your Sales Strategy with Our Proven Framework
A10: /frequently-asked-questions/ | B10: =len(A10) -> 28 | C10: 65 | D10: 0 | E10: 57 | F10: 0.21538462 | G10: 11 | H10: 51 | I10: 64 | J10: 57 | K10: 57.684211 | L10: =vlookup(A10,salesx_all!B:E,2,0) -> Frequently Asked Questions | M10: =vlookup(A10,salesx_all!B:D,3,0) -> General Questions | N10: =vlookup(A10,salesx_all!B:E,4,0) -> Engagement & Pricing
A11: /private-equity-solutions/healthcare-managed-services-case-study/ | B11: =len(A11) -> 65 | C11: 62 | D11: 0 | E11: 60 | F11: 0.33870968 | G11: 27 | H11: 41 | I11: 61 | J11: 60 | K11: 27.016667 | L11: =vlookup(A11,salesx_all!B:E,2,0) -> Company Profile and Challenges | M11: =vlookup(A11,salesx_all!B:D,3,0) -> 25x Return On Investment In One Year: How Sales Xceleration Increased Value | N11: =vlookup(A11,salesx_all!B:E,4,0) -> Platform/Portfolio Company Challenges
A12: /turn-chaos-into-clarity-building-sales-infrastructure-that-scales/ | B12: =len(A12) -> 67 | C12: 59 | D12: 0 | E12: 56 | F12: 0.38983051 | G12: 26 | H12: 36 | I12: 50 | J12: 56 | K12: 7.9107143 | L12: =vlookup(A12,salesx_all!B:E,2,0) -> #N/A | M12: =vlookup(A12,salesx_all!B:D,3,0) -> #N/A | N12: =vlookup(A12,salesx_all!B:E,4,0) -> #N/A
A13: /private-equity-solutions/private-equity/ | B13: =len(A13) -> 41 | C13: 57 | D13: 0 | E13: 42 | F13: 0.45614035 | G13: 10 | H13: 31 | I13: 59 | J13: 40 | K13: 22.925 | L13: =vlookup(A13,salesx_all!B:E,2,0) -> Private Equity Growth with Expert Sales Strategies | M13: =vlookup(A13,salesx_all!B:D,3,0) -> Accelerate Growth. Maximize Returns. | N13: =vlookup(A13,salesx_all!B:E,4,0) -> Maximizing Organic Growth
... A671: /youve-earned-respect-but-are-you-still-getting-it | B671: =len(A671) -> 50 | C671: 1 | D671: 0 | E671: 1 | F671: 1 | G671: 1 | H671: 0 | I671: 0 | J671: 1 | K671: 0 | L671: =vlookup(A671,salesx_all!B:E,2,0) -> #N/A | M671: =vlookup(A671,salesx_all!B:D,3,0) -> #N/A | N671: =vlookup(A671,salesx_all!B:E,4,0) -> #N/A

Sheet salesx_all
A1: Address | C1: H1-1 | D1: H2-1 | E1: H2-2 | F1: Content Type | G1: Status Code | H1: Status | I1: Indexability | J1: Indexability Status | K1: Title 1 | L1: Title 1 Length | M1: Title 1 Pixel Width | N1: Title 2 | O1: Title 2 Length | P1: Title 2 Pixel Width | Q1: Meta Description 1 | R1: Meta Description 1 Length | S1: Meta Description 1 Pixel Width | T1: Meta Keywords 1 | U1: Meta Keywords 1 Length | V1: H1-1 | W1: H1-1 Length | X1: H1-2 | Y1: H1-2 Length | Z1: H2-1 | AA1: H2-1 Length | AB1: H2-2 | AC1: H2-2 Length | AD1: Meta Robots 1 | AE1: X-Robots-Tag 1 | AF1: Meta Refresh 1 | AG1: Canonical Link Element 1 | AH1: rel="next" 1 | AI1: rel="prev" 1 | AJ1: HTTP rel="next" 1 | AK1: HTTP rel="prev" 1 | AL1: amphtml Link Element | AM1: Size (bytes) | AN1: Transferred (bytes) | AO1: Total Transferred (bytes) | AP1: CO2 (mg) | AQ1: Carbon Rating | AR1: Word Count | AS1: Sentence Count | AT1: Average Words Per Sentence | AU1: Flesch Reading Ease Score | AV1: Readability | AW1: Text Ratio | AX1: Crawl Depth | AY1: Folder Depth | AZ1: Link Score | BA1: Inlinks | BB1: Unique Inlinks | BC1: Unique JS Inlinks | BD1: % of Total | BE1: Outlinks | BF1: Unique Outlinks | BG1: Unique JS Outlinks | BH1: External Outlinks | BI1: Unique External Outlinks | BJ1: Unique External JS Outlinks | BK1: Closest Near Duplicate Match | BL1: No. Near Duplicates | BM1: Spelling Errors | BN1: Grammar Errors | BO1: Hash | BP1: Response Time | BQ1: Last Modified | BR1: Redirect URL | BS1: Redirect Type | BT1: Cookies | BU1: Language | BV1: HTTP Version | BW1: Performance Score | BX1: First Contentful Paint Time (ms) | BY1: Speed Index Time (ms) | BZ1: Largest Contentful Paint Time (ms) | CA1: Time to Interactive (ms) | CB1: Total Blocking Time (ms) | CC1: Cumulative Layout Shift | CD1: Total Size Savings (Bytes) | CE1: Total Time Savings (ms) | CF1: Total Requests | CG1: Total Page Size (Bytes) | CH1: HTML Size (Bytes) | CI1: HTML Count | CJ1: Image Size (Bytes) | CK1: Image Count | CL1: CSS Size (Bytes) | CM1: CSS Count | CN1: JavaScript Size (Bytes) | CO1: JavaScript Count | CP1: Font Size (Bytes) | CQ1: Font Count | CR1: Media Size (Bytes) | CS1: Media Count | CT1: Other Size (Bytes) | CU1: Other Count | CV1: Third Party Size (Bytes) | CW1: Third Party Count | CX1: Core Web Vitals Assessment | CY1: CrUX Largest Contentful Paint Time (ms) | CZ1: CrUX Interaction to Next Paint (ms) | DA1: CrUX Cumulative Layout Shift | DB1: CrUX First Contentful Paint Time (ms) | DC1: Minify CSS Savings (ms) | DD1: Minify CSS Savings (Bytes) | DE1: Minify JavaScript Savings (ms) | DF1: Minify JavaScript Savings (Bytes) | DG1: Reduce Unused CSS Savings (ms) | DH1: Reduce Unused CSS Savings (Bytes) | DI1: Reduce Unused JavaScript Savings (ms) | DJ1: Reduce Unused JavaScript Savings (Bytes) | DK1: JavaScript Execution Time (ms) | DL1: JavaScript Execution Time Category | DM1: Minimize Main-Thread Work (ms) | DN1: Minimize Main-Thread Work Category | DO1: Network Payload Size (Bytes) | DP1: User Timing Marks and Measures | DQ1: Number of Redirects | DR1: Server Responds Quickly | DS1: Applies Text Compression | DT1: LCP Request Discovery | DU1: LCP Breakdown | DV1: Render Blocking Requests Savings (ms) | DW1: Preconnect Candidates Savings (ms) | DX1: Maximum Critical Path Latency (ms) | DY1: Use Efficient Cache Lifetimes Savings (Bytes) | DZ1: Layout Shift Culprits | EA1: DOM Size | EB1: Improve Image Delivery Savings (Bytes) | EC1: Forced Reflow Savings (ms) | ED1: Legacy JavaScript Savings (Bytes) | EE1: Duplicated JavaScript (Bytes) | EF1: Font Display Savings (ms) | EG1: 3rd Parties | EH1: Target Size | EI1: Content Width | EJ1: Font Display Size | EK1: Viewport | EL1: Mobile Alternate Link | EM1: Closest Semantically Similar Address | EN1: Semantic Similarity Score | EO1: No. Semantically Similar | EP1: Semantic Relevance Score | EQ1: URL Encoded Address | ER1: Crawl Timestamp
A2: https://salesxceleration.com/ | B2: =IFERROR(__xludf.DUMMYFUNCTION("REGEXREPLACE(A2, ""^https?://[^/]+"", """")"),"/") -> / | C2: Fractional Sales Leadership. Full-Time Results. | D2: Fractional Sales Leaders | E2: A Sales System That Works | F2: text/html; charset=UTF-8 | G2: 200 | H2: OK | I2: Indexable | K2: Sales Xceleration | Outsourced & Fractional Sales Leadership | L2: 60 | M2: 543 | O2: 0 | P2: 0 | Q2: Sales Xceleration offers expert sales outsourcing services. Our outsourced VPs of Sales implement custom strategies to drive growth and improve sales performance. | R2: 162 | S2: 1020 | U2: 0 | V2: Fractional Sales Leadership. Full-Time Results. | W2: 47 | X2: Case Studies | Y2: 12 | Z2: Fractional Sales Leaders | AA2: 24 | AB2: A Sales System That Works | AC2: 25 | AD2: follow, index, max-snippet:-1, max-video-preview:-1, max-image-preview:large | AG2: https://salesxceleration.com/ | AM2: 749412 | AN2: 234736 | AO2: 234736 | AP2: 89.923 | AR2: 1084 | AS2: 188 | AT2: 5.766 | AU2: 54.571 | AV2: Fairly Hard | AW2: 1.671 | AX2: 0 | AY2: 0 | AZ2: 51 | BA2: 833 | BB2: 754 | BC2: 0 | BD2: 100 | BE2: 155 | BF2: 49 | BG2: 0 | BH2: 23 | BI2: 15 | BJ2: 0 | BO2: 527b62052cd29133fd46d9a8ac7da70c | BP2: 1.503 | BU2: en-US | BV2: 1.1 | BW2: 46 | BX2: 3483.699 | BY2: 11076.143 | BZ2: 8477.052 | CA2: 18820.639 | CB2: 547.5 | CC2: 0 | CD2: 640679 | CE2: 1200 | CF2: 193 | CG2: 3456960 | CH2: 223563 | CI2: 2 | CJ2: 1087842 | CK2: 44 | CL2: 118644 | CM2: 42 | CN2: 1756303 | CO2: 70 | CP2: 244245 | CQ2: 5 | CR2: 0 | CS2: 0 | CT2: 26363 | CU2: 30 | CV2: 1505251 | CW2: 90 | DC2: 0 | DD2: 5075 | DE2: 0 | DF2: 3395 | DG2: 150 | DH2: 40137 | DI2: 1050 | DJ2: 592072 | DK2: 2259.466 | DL2: Poor | DM2: 8762.409 | DN2: Poor | DO2: 3456624 | DP2: 1 | DQ2: Avoids redirects | DR2: Server responded slowly (observed 666 ms) | DS2: Applies text compression | DT2: 1 issue found | DU2: 4 resources found | DV2: 14509 | DX2: 6584 | DY2: 1014690 | DZ2: 1 resource found | EA2: 1885 | EB2: 493678 | EC2: 70 | ED2: 26482 | EF2: 245 | EG2: 21 resources found | EH2: 100 | EK2: 100 | EQ2: https://salesxceleration.com/ | ER2: 46045.298
A3: https://salesxceleration.com/wp-includes/js/jquery/ui/core.min.js?ver=1.13.3 | B3: =IFERROR(__xludf.DUMMYFUNCTION("REGEXREPLACE(A3, ""^https?://[^/]+"", """")"),"/wp-includes/js/jquery/ui/core.min.js?ver=1.13.3") -> /wp-includes/js/jquery/ui/core.min.js?ver=1.13.3 | F3: application/javascript | G3: 200 | H3: OK | I3: Indexable | L3: 0 | M3: 0 | O3: 0 | P3: 0 | R3: 0 | S3: 0 | U3: 0 | W3: 0 | Y3: 0 | AA3: 0 | AC3: 0 | AM3: 7106 | AN3: 7106 | AO3: 7106 | AP3: 2.722 | AR3: 0 | AW3: 0 | AX3: 1 | AY3: 4 | BA3: 0 | BB3: 0 | BC3: 0 | BD3: 0 | BE3: 0 | BF3: 0 | BG3: 0 | BH3: 0 | BI3: 0 | BJ3: 0 | BP3: 0.277 | BQ3: Mon, 30 Jun 2025 09:09:57 GMT | BV3: 1.1 | EQ3: https://salesxceleration.com/wp-includes/js/jquery/ui/core.min.js?ver=1.13.3 | ER3: 46045.298
A4: https://salesxceleration.com/privacy-policy/ | B4: =IFERROR(__xludf.DUMMYFUNCTION("REGEXREPLACE(A4, ""^https?://[^/]+"", """")"),"/privacy-policy/") -> /privacy-policy/ | C4: Privacy Policy | F4: text/html; charset=UTF-8 | G4: 200 | H4: OK | I4: Indexable | K4: Privacy Policy | Sales Xceleration | L4: 34 | M4: 294 | O4: 0 | P4: 0 | Q4: Sales Xceleration Privacy Policy | R4: 32 | S4: 195 | U4: 0 | V4: Privacy Policy | W4: 14 | Y4: 0 | AA4: 0 | AC4: 0 | AD4: follow, index, max-snippet:-1, max-video-preview:-1, max-image-preview:large | AG4: https://salesxceleration.com/privacy-policy/ | AM4: 155868 | AN4: 31691 | AO4: 31691 | AP4: 12.14 | AR4: 1736 | AS4: 248 | AT4: 7 | AU4: 60.159 | AV4: Normal | AW4: 8.422 | AX4: 1 | AY4: 1 | AZ4: 51 | BA4: 754 | BB4: 754 | BC4: 0 | BD4: 100 | BE4: 122 | BF4: 42 | BG4: 0 | BH4: 17 | BI4: 9 | BJ4: 0 | BO4: 90fff5e7b8045ce60a195168030ee65 | BP4: 1.377 | BU4: en-US | BV4: 1.1 | BW4: 63 | BX4: 3301.045 | BY4: 9498.224 | BZ4: 5851.083 | CA4: 17963.547 | CB4: 85.5 | CC4: 0.002 | CD4: 652279 | CE4: 1470 | CF4: 155 | CG4: 2199934 | CH4: 33025 | CI4: 2 | CJ4: 17473 | CK4: 15 | CL4: 110635 | CM4: 36 | CN4: 1747376 | CO4: 67 | CP4: 266182 | CQ4: 6 | CR4: 0 | CS4: 0 | CT4: 25243 | CU4: 29 | CV4: 1526753 | CW4: 66 | DC4: 210 | DD4: 5075 | DE4: 0 | DF4: 3396 | DG4: 510 | DH4: 50541 | DI4: 750 | DJ4: 593267 | DK4: 1147.732 | DL4: Good | DM4: 2122.415 | DN4: Poor | DO4: 2199935 | DP4: 1 | DQ4: Avoids redirects | DR4: Server responds quickly (observed 170 ms) | DS4: Applies text compression | DU4: 2 resources found | DV4: 13503 | DW4: 312 | DX4: 5323 | DY4: 579497 | DZ4: 1 resource found | EA4: 807 | EB4: 4453 | EC4: 0 | ED4: 26491 | EF4: 660 | EG4: 21 resources found | EH4: 100 | EK4: 100 | EQ4: https://salesxceleration.com/privacy-policy/ | ER4: 46045.298
A5: https://salesxceleration.com/blog/ | B5: =IFERROR(__xludf.DUMMYFUNCTION("REGEXREPLACE(A5, ""^https?://[^/]+"", """")"),"/blog/") -> /blog/ | C5: Expert Sales Tips and Insights from Sales Xceleration | D5: Not sure where to start? Here are our top picks: | E5: Complete Library | F5: text/html; charset=UTF-8 | G5: 200 | H5: OK | I5: Indexable | K5: Sales Expert Blog | Sales Tips & Insights | Sales Xceleration | L5: 61 | M5: 525 | O5: 0 | P5: 0 | Q5: Explore Sales Xceleration's expert blog for valuable sales tips & insights. Stay ahead with expert advice from industry leaders. | R5: 128 | S5: 768 | U5: 0 | V5: Expert Sales Tips and Insights from Sales Xceleration | W5: 53 | Y5: 0 | Z5: Not sure where to start? Here are our top picks: | AA5: 48 | AB5: Complete Library | AC5: 16 | AD5: follow, index, max-snippet:-1, max-video-preview:-1, max-image-preview:large | AG5: https://salesxceleration.com/blog/ | AM5: 187541 | AN5: 33755 | AO5: 33755 | AP5: 12.931 | AR5: 1117 | AS5: 210 | AT5: 5.319 | AU5: 67.152 | AV5: Normal | AW5: 4.895 | AX5: 1 | AY5: 1 | AZ5: 52 | BA5: 3020 | BB5: 754 | BC5: 0 | BD5: 100 | BE5: 149 | BF5: 53 | BG5: 0 | BH5: 16 | BI5: 8 | BJ5: 0 | BO5: ce57e6117f2da7436d8c7e3fda3baf61 | BP5: 1.567 | BU5: en-US | BV5: 1.1 | BW5: 57 | BX5: 3451.025 | BY5: 8592.665 | BZ5: 7502.059 | CA5: 18048.385 | CB5: 191 | CC5: 0 | CD5: 652819 | CE5: 1200 | CF5: 175 | CG5: 2462041 | CH5: 34568 | CI5: 2 | CJ5: 175038 | CK5: 23 | CL5: 119532 | CM5: 42 | CN5: 1765138 | CO5: 71 | CP5: 341323 | CQ5: 8 | CR5: 0 | CS5: 0 | CT5: 26442 | CU5: 29 | CV5: 1527688 | CW5: 72 | DC5: 0 | DD5: 5075 | DE5: 0 | DF5: 3401 | DG5: 150 | DH5: 50545 | DI5: 1050 | DJ5: 593798 | DK5: 1132.225 | DL5: Good | DM5: 2206.643 | DN5: Poor | DO5: 2461125 | DP5: 1 | DQ5: Avoids redirects | DR5: Server responds quickly (observed 181 ms) | DS5: Applies text compression | DU5: 2 resources found | DV5: 14240 | DX5: 5090 | DY5: 683140 | DZ5: 1 resource found | EA5: 990 | EB5: 4453 | EC5: 0 | ED5: 26491 | EF5: 665 | EG5: 21 resources found | EH5: 100 | EK5: 100 | EQ5: https://salesxceleration.com/blog/ | ER5: 46045.298
A6: https://salesxceleration.com/wp-content/uploads/2025/02/Fractional-Sales-Leader-1-1024x929.jpg | B6: =IFERROR(__xludf.DUMMYFUNCTION("REGEXREPLACE(A6, ""^https?://[^/]+"", """")"),"/wp-content/uploads/2025/02/Fractional-Sales-Leader-1-1024x929.jpg") -> /wp-content/uploads/2025/02/Fractional-Sales-Leader-1-1024x929.jpg | F6: image/jpeg | G6: 200 | H6: OK | I6: Indexable | L6: 0 | M6: 0 | O6: 0 | P6: 0 | R6: 0 | S6: 0 | U6: 0 | W6: 0 | Y6: 0 | AA6: 0 | AC6: 0 | AM6: 115655 | AN6: 115655 | AO6: 115655 | AP6: 44.305 | AR6: 0 | AW6: 0 | AX6: 1 | AY6: 4 | BA6: 0 | BB6: 0 | BC6: 0 | BD6: 0 | BE6: 0 | BF6: 0 | BG6: 0 | BH6: 0 | BI6: 0 | BJ6: 0 | BP6: 0.282 | BQ6: Wed, 26 Feb 2025 14:31:07 GMT | BV6: 1.1 | EQ6: https://salesxceleration.com/wp-content/uploads/2025/02/Fractional-Sales-Leader-1-1024x929.jpg | ER6: 46045.298
A7: https://salesxceleration.com/wp-includes/js/dist/hooks.min.js?ver=dd5603f07f9220ed27f1 | B7: =IFERROR(__xludf.DUMMYFUNCTION("REGEXREPLACE(A7, ""^https?://[^/]+"", """")"),"/wp-includes/js/dist/hooks.min.js?ver=dd5603f07f9220ed27f1") -> /wp-includes/js/dist/hooks.min.js?ver=dd5603f07f9220ed27f1 | F7: application/javascript | G7: 200 | H7: OK | I7: Indexable | L7: 0 | M7: 0 | O7: 0 | P7: 0 | R7: 0 | S7: 0 | U7: 0 | W7: 0 | Y7: 0 | AA7: 0 | AC7: 0 | AM7: 1941 | AN7: 1941 | AO7: 1941 | AP7: 0.744 | AR7: 0 | AW7: 0 | AX7: 1 | AY7: 3 | BA7: 0 | BB7: 0 | BC7: 0 | BD7: 0 | BE7: 0 | BF7: 0 | BG7: 0 | BH7: 0 | BI7: 0 | BJ7: 0 | BP7: 0.274 | BQ7: Fri, 02 Jan 2026 17:49:24 GMT | BV7: 1.1 | EQ7: https://salesxceleration.com/wp-includes/js/dist/hooks.min.js?ver=dd5603f07f9220ed27f1 | ER7: 46045.298
A8: https://salesxceleration.com/client-solutions/ | B8: =IFERROR(__xludf.DUMMYFUNCTION("REGEXREPLACE(A8, ""^https?://[^/]+"", """")"),"/client-solutions/") -> /client-solutions/ | C8: Tailored Sales Solutions for Your Business | D8: Fractional Sales Leader: Your Source for Sales Success | E8: Certified Sales Operating Management SystemTM | F8: text/html; charset=UTF-8 | G8: 200 | H8: OK | I8: Indexable | K8: Expert Sales Consulting & Growth Strategies | Sales Xceleration | L8: 63 | M8: 566 | O8: 0 | P8: 0 | Q8: Unlock business success with Sales Xceleration's expert sales consulting and proven sales growth strategies to build a high-performing team and drive revenue growth. | R8: 165 | S8: 1029 | U8: 0 | V8: Tailored Sales Solutions for Your Business | W8: 42 | Y8: 0 | Z8: Fractional Sales Leader: Your Source for Sales Success | AA8: 54 | AB8: Certified Sales Operating Management SystemTM | AC8: 45 | AD8: follow, index, max-snippet:-1, max-video-preview:-1, max-image-preview:large | AG8: https://salesxceleration.com/client-solutions/ | AM8: 185916 | AN8: 32816 | AO8: 32816 | AP8: 12.571 | AR8: 1161 | AS8: 189 | AT8: 6.143 | AU8: 58.07 | AV8: Fairly Hard | AW8: 5.276 | AX8: 1 | AY8: 1 | AZ8: 51 | BA8: 3028 | BB8: 754 | BC8: 0 | BD8: 100 | BE8: 133 | BF8: 42 | BG8: 0 | BH8: 18 | BI8: 9 | BJ8: 0 | BO8: 7fb40fed596000750dd96c59c0d6edf2 | BP8: 2.036 | BU8: en-US | BV8: 1.1 | BW8: 52 | BX8: 3451.03 | BY8: 6824.549 | BZ8: 7651.07 | CA8: 18030.395 | CB8: 423 | CC8: 0.008 | CD8: 652554 | CE8: 1050 | CF8: 165 | CG8: 2580585 | CH8: 34342 | CI8: 2 | CJ8: 342637 | CK8: 22 | CL8: 113095 | CM8: 37 | CN8: 1749022 | CO8: 69 | CP8: 316830 | CQ8: 7 | CR8: 0 | CS8: 0 | CT8: 24659 | CU8: 28 | CV8: 1526775 | CW8: 69 | DC8: 0 | DD8: 5075 | DE8: 0 | DF8: 3396 | DG8: 150 | DH8: 50502 | DI8: 900 | DJ8: 593581 | DK8: 1776.936 | DL8: Poor | DM8: 3219.756 | DN8: Poor | DO8: 2580157 | DP8: 1 | DQ8: Avoids redirects | DR8: Server responds quickly (observed 171 ms) | DS8: Applies text compression | DT8: 1 issue found | DU8: 4 resources found | DV8: 12640 | DX8: 3806 | DY8: 731215 | DZ8: 1 resource found | EA8: 1024 | EB8: 29477 | EC8: 1 | ED8: 26491 | EF8: 260 | EG8: 21 resources found | EH8: 100 | EK8: 100 | EQ8: https://salesxceleration.com/client-solutions/ | ER8: 46045.298
A9: https://salesxceleration.com/wp-content/plugins/elementor/assets/css/frontend.min.css?ver=3.34.0 | B9: =IFERROR(__xludf.DUMMYFUNCTION("REGEXREPLACE(A9, ""^https?://[^/]+"", """")"),"/wp-content/plugins/elementor/assets/css/frontend.min.css?ver=3.34.0") -> /wp-content/plugins/elementor/assets/css/frontend.min.css?ver=3.34.0 | F9: text/css | G9: 200 | H9: OK | I9: Indexable | L9: 0 | M9: 0 | O9: 0 | P9: 0 | R9: 0 | S9: 0 | U9: 0 | W9: 0 | Y9: 0 | AA9: 0 | AC9: 0 | AM9: 7244 | AN9: 7244 | AO9: 7244 | AP9: 2.775 | AR9: 0 | AW9: 0 | AX9: 1 | AY9: 5 | BA9: 0 | BB9: 0 | BC9: 0 | BD9: 0 | BE9: 0 | BF9: 0 | BG9: 0 | BH9: 0 | BI9: 0 | BJ9: 0 | BP9: 0.282 | BQ9: Fri, 02 Jan 2026 17:29:45 GMT | BV9: 1.1 | EQ9: https://salesxceleration.com/wp-content/plugins/elementor/assets/css/frontend.min.css?ver=3.34.0 | ER9: 46045.298
A10: https://salesxceleration.com/sales-team/ | B10: =IFERROR(__xludf.DUMMYFUNCTION("REGEXREPLACE(A10, ""^https?://[^/]+"", """")"),"/sales-team/") -> /sales-team/ | C10: Sales Team Development Services | D10: Your Foundation for Scalable and Efficient Growth | E10: Read Real Success Stories | F10: text/html; charset=UTF-8 | G10: 200 | H10: OK | I10: Indexable | K10: Sales Team Development | Build, Lead & Train High-Performing Sales Teams | L10: 72 | M10: 684 | O10: 0 | P10: 0 | Q10: Develop your sales team with Sales Xceleration’s proven recruiting, leadership, and training solutions from experienced fractional leaders. Get connected today. | R10: 160 | S10: 979 | U10: 0 | V10: Sales Team Development Services | W10: 31 | Y10: 0 | Z10: Your Foundation for Scalable and Efficient Growth | AA10: 49 | AB10: Read Real Success Stories | AC10: 25 | AD10: follow, index, max-snippet:-1, max-video-preview:-1, max-image-preview:large | AG10: https://salesxceleration.com/sales-team/ | AM10: 585622 | AN10: 167805 | AO10: 167805 | AP10: 64.283 | AR10: 1167 | AS10: 193 | AT10: 6.047 | AU10: 58.103 | AV10: Fairly Hard | AW10: 1.87 | AX10: 1 | AY10: 1 | AZ10: 51 | BA10: 2289 | BB10: 754 | BC10: 0 | BD10: 100 | BE10: 134 | BF10: 45 | BG10: 0 | BH10: 16 | BI10: 8 | BJ10: 0 | BO10: fc7092c005ccb140fcb0f92815f24b98 | BP10: 1.037 | BU10: en-US | BV10: 1.1 | BW10: 43 | BX10: 4051.026 | BY10: 8900.939 | BZ10: 6913.624 | CA10: 19438.924 | CB10: 699.031 | CC10: 0.008 | CD10: 664646 | CE10: 1360 | CF10: 179 | CG10: 2394913 | CH10: 159012 | CI10: 2 | CJ10: 17648 | CK10: 23 | CL10: 127574 | CM10: 47 | CN10: 1798717 | CO10: 72 | CP10: 266193 | CQ10: 6 | CR10: 0 | CS10: 0 | CT10: 25769 | CU10: 29 | CV10: 1526933 | CW10: 74 | DC10: 0 | DD10: 5075 | DE10: 0 | DF10: 3396 | DG10: 300 | DH10: 40162 | DI10: 1060 | DJ10: 616013 | DK10: 2127.931 | DL10: Poor | DM10: 5281.125 | DN10: Poor | DO10: 2394746 | DP10: 1 | DQ10: Avoids redirects | DR10: Server responds quickly (observed 516 ms) | DS10: Applies text compression | DU10: 2 resources found | DV10: 14996 | DW10: 321 | DX10: 4067 | DY10: 606926 | DZ10: 1 resource found | EA10: 1711 | EB10: 4453 | EC10: 55 | ED10: 26491 | EF10: 400 | EG10: 21 resources found | EH10: 100 | EK10: 100 | EQ10: https://salesxceleration.com/sales-team/ | ER10: 46045.298
A11: https://salesxceleration.com/state-of-sales/ | B11: =IFERROR(__xludf.DUMMYFUNCTION("REGEXREPLACE(A11, ""^https?://[^/]+"", """")"),"/state-of-sales/") -> /state-of-sales/ | C11: 2025 State of Sales | Small to Mid-Size Businesses | D11: The State of Sales: Crafting High-Performing Sales Organizations | E11: Sales Strategy | F11: text/html; charset=UTF-8 | G11: 200 | H11: OK | I11: Indexable | K11: State of Sales Report | Trends and Insights | Sales Xceleration | L11: 63 | M11: 550 | O11: 0 | P11: 0 | Q11: Get the latest sales performance trends and insights with Sales Xceleration's State of Sales report. Enhance your sales strategy. | R11: 129 | S11: 786 | U11: 0 | V11: 2025 State of Sales | Small to Mid-Size Businesses | W11: 50 | Y11: 0 | Z11: The State of Sales: Crafting High-Performing Sales Organizations | AA11: 64 | AB11: Sales Strategy | AC11: 14 | AD11: follow, index, max-snippet:-1, max-video-preview:-1, max-image-preview:large | AG11: https://salesxceleration.com/state-of-sales/ | AM11: 327338 | AN11: 48949 | AO11: 48949 | AP11: 18.751 | AR11: 1964 | AS11: 332 | AT11: 5.916 | AU11: 58.423 | AV11: Fairly Hard | AW11: 4.576 | AX11: 1 | AY11: 1 | AZ11: 51 | BA11: 2268 | BB11: 754 | BC11: 0 | BD11: 100 | BE11: 139 | BF11: 47 | BG11: 0 | BH11: 18 | BI11: 8 | BJ11: 0 | BO11: cfe8f6e611a808b12a2a28ed209d7de0 | BP11: 1.124 | BU11: en-US | BV11: 1.1 | BW11: 56 | BX11: 3901.013 | BY11: 7851.421 | BZ11: 7051.025 | CA11: 19822.342 | CB11: 264 | CC11: 0 | CD11: 689726 | CE11: 750 | CF11: 213 | CG11: 2595260 | CH11: 49362 | CI11: 2 | CJ11: 151823 | CK11: 34 | CL11: 166879 | CM11: 56 | CN11: 1857672 | CO11: 82 | CP11: 343690 | CQ11: 8 | CR11: 0 | CS11: 1 | CT11: 25834 | CU11: 30 | CV11: 1531214 | CW11: 81 | DC11: 0 | DD11: 5075 | DE11: 0 | DF11: 3396 | DG11: 150 | DH11: 68104 | DI11: 600 | DJ11: 613151 | DK11: 1640.404 | DL11: Poor | DM11: 4453.969 | DN11: Poor | DO11: 2594526 | DP11: 1 | DQ11: Avoids redirects | DR11: Server responds quickly (observed 324 ms) | DS11: Applies text compression | DU11: 2 resources found | DV11: 16557 | DX11: 4531 | DY11: 729205 | EA11: 1645 | EB11: 4453 | EC11: 50 | ED11: 26491 | EF11: 230 | EG11: 22 resources found | EH11: 100 | EK11: 100 | EQ11: https://salesxceleration.com/state-of-sales/ | ER11: 46045.298
A12: https://salesxceleration.com/industries/private-equity/ | B12: =IFERROR(__xludf.DUMMYFUNCTION("REGEXREPLACE(A12, ""^https?://[^/]+"", """")"),"/industries/private-equity/") -> /industries/private-equity/ | C12: Fractional Sales Leadership for Private Equity | D12: Key Sales Challenges in Private Equity | E12: Why Fractional Sales Leadership Fits Private Equity | F12: text/html; charset=UTF-8 | G12: 200 | H12: OK | I12: Indexable | K12: Fractional Sales Leadership for Private Equity | Sales Xceleration | L12: 66 | M12: 576 | O12: 0 | P12: 0 | Q12: Accelerate portfolio company growth with fractional sales leadership. We drive revenue and maximize exit multiples. Schedule a Consultation. | R12: 140 | S12: 870 | U12: 0 | V12: Fractional Sales Leadership for Private Equity | W12: 46 | Y12: 0 | Z12: Key Sales Challenges in Private Equity | AA12: 38 | AB12: Why Fractional Sales Leadership Fits Private Equity | AC12: 51 | AD12: follow, index, max-snippet:-1, max-video-preview:-1, max-image-preview:large | AG12: https://salesxceleration.com/industries/private-equity/ | AM12: 277166 | AN12: 90934 | AO12: 90934 | AP12: 34.835 | AR12: 1569 | AS12: 258 | AT12: 6.081 | AU12: 52.275 | AV12: Fairly Hard | AW12: 6.515 | AX12: 1 | AY12: 2 | AZ12: 51 | BA12: 2250 | BB12: 754 | BC12: 0 | BD12: 100 | BE12: 136 | BF12: 47 | BG12: 0 | BH12: 16 | BI12: 8 | BJ12: 0 | BO12: 5cd596601cdc2f7e876c4bb3fef0d1ef | BP12: 1.096 | BU12: en-US | BV12: 1.1 | BW12: 62 | BX12: 3751.009 | BY12: 7966.564 | BZ12: 6977.017 | CA12: 17927.074 | CB12: 64.5 | CC12: 0.023 | CD12: 672681 | CE12: 750 | CF12: 179 | CG12: 3144053 | CH12: 89262 | CI12: 2 | CJ12: 762997 | CK12: 27 | CL12: 126361 | CM12: 44 | CN12: 1791292 | CO12: 71 | CP12: 348792 | CQ12: 6 | CR12: 0 | CS12: 0 | CT12: 25349 | CU12: 29 | CV12: 1504890 | CW12: 76 | DC12: 0 | DD12: 5075 | DE12: 0 | DF12: 3396 | DG12: 150 | DH12: 50543 | DI12: 600 | DJ12: 613667 | DK12: 1137.666 | DL12: Good | DM12: 2152.411 | DN12: Poor | DO12: 3143891 | DP12: 1 | DQ12: Avoids redirects | DR12: Server responds quickly (observed 339 ms) | DS12: Applies text compression | DU12: 2 resources found | DV12: 13847 | DX12: 3934 | DY12: 943387 | DZ12: 1 resource found | EA12: 1177 | EB12: 499109 | EC12: 50 | ED12: 26491 | EF12: 240 | EG12: 21 resources found | EH12: 100 | EK12: 100 | EQ12: https://salesxceleration.com/industries/private-equity/ | ER12: 46045.298
A13: https://salesxceleration.com/wp-content/plugins/elementor-pro/assets/js/webpack-pro.runtime.min.js?ver=3.34.0 | B13: =IFERROR(__xludf.DUMMYFUNCTION("REGEXREPLACE(A13, ""^https?://[^/]+"", """")"),"/wp-content/plugins/elementor-pro/assets/js/webpack-pro.runtime.min.js?ver=3.34.0") -> /wp-content/plugins/elementor-pro/assets/js/webpack-pro.runtime.min.js?ver=3.34.0 | F13: application/javascript | G13: 200 | H13: OK | I13: Indexable | L13: 0 | M13: 0 | O13: 0 | P13: 0 | R13: 0 | S13: 0 | U13: 0 | W13: 0 | Y13: 0 | AA13: 0 | AC13: 0 | AM13: 2856 | AN13: 2856 | AO13: 2856 | AP13: 1.094 | AR13: 0 | AW13: 0 | AX13: 1 | AY13: 5 | BA13: 0 | BB13: 0 | BC13: 0 | BD13: 0 | BE13: 0 | BF13: 0 | BG13: 0 | BH13: 0 | BI13: 0 | BJ13: 0 | BP13: 0.279 | BQ13: Fri, 02 Jan 2026 17:52:08 GMT | BV13: 1.1 | EQ13: https://salesxceleration.com/wp-content/plugins/elementor-pro/assets/js/webpack-pro.runtime.min.js?ver=3.34.0 | ER13: 46045.298
A14: https://salesxceleration.com/wp-content/uploads/2022/09/ciobulletin-50-best-companies-to-watch-2022-logo.jpg | B14: =IFERROR(__xludf.DUMMYFUNCTION("REGEXREPLACE(A14, ""^https?://[^/]+"", """")"),"/wp-content/uploads/2022/09/ciobulletin-50-best-companies-to-watch-2022-logo.jpg") -> /wp-content/uploads/2022/09/ciobulletin-50-best-companies-to-watch-2022-logo.jpg | F14: image/jpeg | G14: 200 | H14: OK | I14: Indexable | L14: 0 | M14: 0 | O14: 0 | P14: 0 | R14: 0 | S14: 0 | U14: 0 | W14: 0 | Y14: 0 | AA14: 0 | AC14: 0 | AM14: 30241 | AN14: 30241 | AO14: 30241 | AP14: 11.585 | AR14: 0 | AW14: 0 | AX14: 1 | AY14: 4 | BA14: 0 | BB14: 0 | BC14: 0 | BD14: 0 | BE14: 0 | BF14: 0 | BG14: 0 | BH14: 0 | BI14: 0 | BJ14: 0 | BP14: 0.267 | BQ14: Thu, 22 Sep 2022 17:13:23 GMT | BV14: 1.1 | EQ14: https://salesxceleration.com/wp-content/uploads/2022/09/ciobulletin-50-best-companies-to-watch-2022-logo.jpg | ER14: 46045.298
A15: https://salesxceleration.com/wp-content/themes/salesxceleratione/assets/js/jquery.mixitup.js?ver=2.1.11 | B15: =IFERROR(__xludf.DUMMYFUNCTION("REGEXREPLACE(A15, ""^https?://[^/]+"", """")"),"/wp-content/themes/salesxceleratione/assets/js/jquery.mixitup.js?ver=2.1.11") -> /wp-content/themes/salesxceleratione/assets/js/jquery.mixitup.js?ver=2.1.11 | F15: application/javascript | G15: 200 | H15: OK | I15: Indexable | L15: 0 | M15: 0 | O15: 0 | P15: 0 | R15: 0 | S15: 0 | U15: 0 | W15: 0 | Y15: 0 | AA15: 0 | AC15: 0 | AM15: 11141 | AN15: 11141 | AO15: 11141 | AP15: 4.268 | AR15: 0 | AW15: 0 | AX15: 1 | AY15: 5 | BA15: 0 | BB15: 0 | BC15: 0 | BD15: 0 | BE15: 0 | BF15: 0 | BG15: 0 | BH15: 0 | BI15: 0 | BJ15: 0 | BP15: 0.267 | BQ15: Fri, 12 Nov 2021 15:43:34 GMT | BV15: 1.1 | EQ15: https://salesxceleration.com/wp-content/themes/salesxceleratione/assets/js/jquery.mixitup.js?ver=2.1.11 | ER15: 46045.298
A16: https://salesxceleration.com/wp-content/uploads/2025/04/logo-eos-300x198-1.png | B16: =IFERROR(__xludf.DUMMYFUNCTION("REGEXREPLACE(A16, ""^https?://[^/]+"", """")"),"/wp-content/uploads/2025/04/logo-eos-300x198-1.png") -> /wp-content/uploads/2025/04/logo-eos-300x198-1.png | F16: image/png | G16: 200 | H16: OK | I16: Indexable | L16: 0 | M16: 0 | O16: 0 | P16: 0 | R16: 0 | S16: 0 | U16: 0 | W16: 0 | Y16: 0 | AA16: 0 | AC16: 0 | AM16: 38512 | AN16: 38512 | AO16: 38512 | AP16: 14.753 | AR16: 0 | AW16: 0 | AX16: 1 | AY16: 4 | BA16: 0 | BB16: 0 | BC16: 0 | BD16: 0 | BE16: 0 | BF16: 0 | BG16: 0 | BH16: 0 | BI16: 0 | BJ16: 0 | BP16: 0.318 | BQ16: Wed, 16 Apr 2025 14:18:45 GMT | BV16: 1.1 | EQ16: https://salesxceleration.com/wp-content/uploads/2025/04/logo-eos-300x198-1.png | ER16: 46045.298
A17: https://salesxceleration.com/case-study/electrical-manufacturing-sales-strategy-and-processes-provide-immediate-growth/ | B17: =IFERROR(__xludf.DUMMYFUNCTION("REGEXREPLACE(A17, ""^https?://[^/]+"", """")"),"/case-study/electrical-manufacturing-sales-strategy-and-processes-provide-immediate-growth/") -> /case-study/electrical-manufacturing-sales-strategy-and-processes-provide-immediate-growth/ | C17: Electrical Manufacturing: Sales Strategy and Processes Provide Immediate Growth | D17: Executive Summary | E17: The Big Win | F17: text/html; charset=UTF-8 | G17: 200 | H17: OK | I17: Indexable | K17: Case Study - Electrical Manufacturer Grows 65%+ with Sales Strategy | L17: 67 | M17: 616 | O17: 0 | P17: 0 | Q17: With expert guidance from an Outsourced VP of Sales, an electrical manufacturer achieved 20% quarterly growth, setting the stage for 65% year-over-year gains. | R17: 158 | S17: 987 | U17: 0 | V17: Electrical Manufacturing: Sales Strategy and Processes Provide Immediate Growth | W17: 79 | Y17: 0 | Z17: Executive Summary | AA17: 17 | AB17: The Big Win | AC17: 11 | AD17: follow, index, max-snippet:-1, max-video-preview:-1, max-image-preview:large | AG17: https://salesxceleration.com/case-study/electrical-manufacturing-sales-strategy-and-processes-provide-immediate-growth/ | AM17: 184741 | AN17: 31627 | AO17: 31627 | AP17: 12.116 | AR17: 895 | AS17: 144 | AT17: 6.215 | AU17: 60.629 | AV17: Normal | AW17: 4.31 | AX17: 1 | AY17: 2 | AZ17: 3 | BA17: 6 | BB17: 4 | BC17: 0 | BD17: 0.53 | BE17: 129 | BF17: 48 | BG17: 0 | BH17: 16 | BI17: 8 | BJ17: 0 | BO17: 32d1911981741b746084633baa3673fa | BP17: 0.99 | BU17: en-US | BV17: 1.1 | BW17: 53 | BX17: 3751.032 | BY17: 8026.796 | BZ17: 9901.088 | CA17: 18141.576 | CB17: 314.345 | CC17: 0 | CD17: 652646 | CE17: 1350 | CF17: 166 | CG17: 2308729 | CH17: 32604 | CI17: 2 | CJ17: 98677 | CK17: 19 | CL17: 119133 | CM17: 43 | CN17: 1747804 | CO17: 68 | CP17: 284714 | CQ17: 6 | CR17: 0 | CS17: 0 | CT17: 25797 | CU17: 28 | CV17: 1505043 | CW17: 65 | DC17: 150 | DD17: 5075 | DE17: 0 | DF17: 3396 | DG17: 150 | DH17: 50530 | DI17: 1050 | DJ17: 593645 | DK17: 1480.596 | DL17: Poor | DM17: 2748.634 | DN17: Poor | DO17: 2307948 | DP17: 1 | DQ17: Avoids redirects | DR17: Server responds quickly (observed 169 ms) | DS17: Applies text compression | DT17: 1 issue found | DU17: 4 resources found | DV17: 14547 | DW17: 314 | DX17: 4898 | DY17: 631708 | EA17: 928 | EB17: 4453 | EC17: 1 | ED17: 26491 | EF17: 245 | EG17: 21 resources found | EH17: 100 | EK17: 100 | EQ17: https://salesxceleration.com/case-study/electrical-manufacturing-sales-strategy-and-processes-provide-immediate-growth/ | ER17: 46045.298
A18: https://salesxceleration.com/wp-content/plugins/elementor/assets/css/widget-video.min.css?ver=3.34.0 | B18: =IFERROR(__xludf.DUMMYFUNCTION("REGEXREPLACE(A18, ""^https?://[^/]+"", """")"),"/wp-content/plugins/elementor/assets/css/widget-video.min.css?ver=3.34.0") -> /wp-content/plugins/elementor/assets/css/widget-video.min.css?ver=3.34.0 | F18: text/css | G18: 200 | H18: OK | I18: Indexable | L18: 0 | M18: 0 | O18: 0 | P18: 0 | R18: 0 | S18: 0 | U18: 0 | W18: 0 | Y18: 0 | AA18: 0 | AC18: 0 | AM18: 404 | AN18: 404 | AO18: 404 | AP18: 0.155 | AR18: 0 | AW18: 0 | AX18: 1 | AY18: 5 | BA18: 0 | BB18: 0 | BC18: 0 | BD18: 0 | BE18: 0 | BF18: 0 | BG18: 0 | BH18: 0 | BI18: 0 | BJ18: 0 | BP18: 0.265 | BQ18: Fri, 02 Jan 2026 17:29:45 GMT | BV18: 1.1 | EQ18: https://salesxceleration.com/wp-content/plugins/elementor/assets/css/widget-video.min.css?ver=3.34.0 | ER18: 46045.298
A19: https://salesxceleration.com/wp-content/uploads/elementor/google-fonts/css/robotoslab.css?ver=1744026309 | B19: =IFERROR(__xludf.DUMMYFUNCTION("REGEXREPLACE(A19, ""^https?://[^/]+"", """")"),"/wp-content/uploads/elementor/google-fonts/css/robotoslab.css?ver=1744026309") -> /wp-content/uploads/elementor/google-fonts/css/robotoslab.css?ver=1744026309 | F19: text/css | G19: 200 | H19: OK | I19: Indexable | L19: 0 | M19: 0 | O19: 0 | P19: 0 | R19: 0 | S19: 0 | U19: 0 | W19: 0 | Y19: 0 | AA19: 0 | AC19: 0 | AM19: 944 | AN19: 944 | AO19: 944 | AP19: 0.362 | AR19: 0 | AW19: 0 | AX19: 1 | AY19: 5 | BA19: 0 | BB19: 0 | BC19: 0 | BD19: 0 | BE19: 0 | BF19: 0 | BG19: 0 | BH19: 0 | BI19: 0 | BJ19: 0 | BP19: 0.265 | BQ19: Mon, 07 Apr 2025 11:45:09 GMT | BV19: 1.1 | EQ19: https://salesxceleration.com/wp-content/uploads/elementor/google-fonts/css/robotoslab.css?ver=1744026309 | ER19: 46045.298
A20: https://salesxceleration.com/case-study/healthcare-consulting-driving-growth-through-effective-strategy-execution-and-training/ | B20: =IFERROR(__xludf.DUMMYFUNCTION("REGEXREPLACE(A20, ""^https?://[^/]+"", """")"),"/case-study/healthcare-consulting-driving-growth-through-effective-strategy-execution-and-training/") -> /case-study/healthcare-consulting-driving-growth-through-effective-strategy-execution-and-training/ | C20: Healthcare Consulting: Driving Growth Through Effective Strategy, Execution, and Training | D20: Executive Summary | E20: The Big Win | F20: text/html; charset=UTF-8 | G20: 200 | H20: OK | I20: Indexable | K20: Case Study - Healthcare Company Grows 45% with Sales Strategy | L20: 61 | M20: 584 | O20: 0 | P20: 0 | Q20: See how a healthcare consulting company partnered with an Outsourced VP of Sales to improve strategy execution, train teams, and drive sustainable growth. | R20: 154 | S20: 977 | U20: 0 | V20: Healthcare Consulting: Driving Growth Through Effective Strategy, Execution, and Training | W20: 89 | Y20: 0 | Z20: Executive Summary | AA20: 17 | AB20: The Big Win | AC20: 11 | AD20: follow, index, max-snippet:-1, max-video-preview:-1, max-image-preview:large | AG20: https://salesxceleration.com/case-study/healthcare-consulting-driving-growth-through-effective-strategy-execution-and-training/ | AM20: 181876 | AN20: 31797 | AO20: 31797 | AP20: 12.181 | AR20: 922 | AS20: 150 | AT20: 6.147 | AU20: 59.29 | AV20: Fairly Hard | AW20: 4.508 | AX20: 1 | AY20: 2 | AZ20: 2 | BA20: 8 | BB20: 4 | BC20: 0 | BD20: 0.53 | BE20: 131 | BF20: 48 | BG20: 0 | BH20: 16 | BI20: 8 | BJ20: 0 | BO20: 69d96f70d37d737e457b09b1cd80ef2 | BP20: 1.003 | BU20: en-US | BV20: 1.1 | BW20: 59 | BX20: 4201.043 | BY20: 6201.606 | BZ20: 9151.098 | CA20: 18472.811 | CB20: 166.5 | CC20: 0 | CD20: 651545 | CE20: 1500 | CF20: 167 | CG20: 2311614 | CH20: 32923 | CI20: 2 | CJ20: 100556 | CK20: 19 | CL20: 119156 | CM20: 43 | CN20: 1748093 | CO20: 68 | CP20: 284714 | CQ20: 6 | CR20: 0 | CS20: 0 | CT20: 26172 | CU20: 29 | CV20: 1506101 | CW20: 65 | DC20: 150 | DD20: 5075 | DE20: 0 | DF20: 3396 | DG20: 300 | DH20: 50530 | DI20: 1050 | DJ20: 592544 | DK20: 1201.831 | DL20: Good | DM20: 2287.766 | DN20: Poor | DO20: 2310938 | DP20: 1 | DQ20: Avoids redirects | DR20: Server responds quickly (observed 173 ms) | DS20: Applies text compression | DT20: 1 issue found | DU20: 4 resources found | DV20: 13876 | DX20: 3757 | DY20: 632077 | EA20: 928 | EB20: 4453 | EC20: 0 | ED20: 26491 | EF20: 235 | EG20: 21 resources found | EH20: 100 | EK20: 100 | EQ20: https://salesxceleration.com/case-study/healthcare-consulting-driving-growth-through-effective-strategy-execution-and-training/ | ER20: 46045.298
A21: https://salesxceleration.com/wp-content/plugins/elementor/assets/js/webpack.runtime.min.js?ver=3.34.0 | B21: =IFERROR(__xludf.DUMMYFUNCTION("REGEXREPLACE(A21, ""^https?://[^/]+"", """")"),"/wp-content/plugins/elementor/assets/js/webpack.runtime.min.js?ver=3.34.0") -> /wp-content/plugins/elementor/assets/js/webpack.runtime.min.js?ver=3.34.0 | F21: application/javascript | G21: 200 | H21: OK | I21: Indexable | L21: 0 | M21: 0 | O21: 0 | P21: 0 | R21: 0 | S21: 0 | U21: 0 | W21: 0 | Y21: 0 | AA21: 0 | AC21: 0 | AM21: 2476 | AN21: 2476 | AO21: 2476 | AP21: 0.949 | AR21: 0 | AW21: 0 | AX21: 1 | AY21: 5 | BA21: 0 | BB21: 0 | BC21: 0 | BD21: 0 | BE21: 0 | BF21: 0 | BG21: 0 | BH21: 0 | BI21: 0 | BJ21: 0 | BP21: 0.259 | BQ21: Fri, 02 Jan 2026 17:29:45 GMT | BV21: 1.1 | EQ21: https://salesxceleration.com/wp-content/plugins/elementor/assets/js/webpack.runtime.min.js?ver=3.34.0 | ER21: 46045.298
A22: https://salesxceleration.com/wp-content/uploads/2023/05/spring23.png | B22: =IFERROR(__xludf.DUMMYFUNCTION("REGEXREPLACE(A22, ""^https?://[^/]+"", """")"),"/wp-content/uploads/2023/05/spring23.png") -> /wp-content/uploads/2023/05/spring23.png | F22: image/png | G22: 200 | H22: OK | I22: Indexable | L22: 0 | M22: 0 | O22: 0 | P22: 0 | R22: 0 | S22: 0 | U22: 0 | W22: 0 | Y22: 0 | AA22: 0 | AC22: 0 | AM22: 24222 | AN22: 24222 | AO22: 24222 | AP22: 9.279 | AR22: 0 | AW22: 0 | AX22: 1 | AY22: 4 | BA22: 0 | BB22: 0 | BC22: 0 | BD22: 0 | BE22: 0 | BF22: 0 | BG22: 0 | BH22: 0 | BI22: 0 | BJ22: 0 | BP22: 1.157 | BQ22: Mon, 15 May 2023 14:07:42 GMT | BV22: 1.1 | EQ22: https://salesxceleration.com/wp-content/uploads/2023/05/spring23.png | ER22: 46045.298
A23: https://salesxceleration.com/wp-content/plugins/elementor/assets/lib/font-awesome/css/fontawesome.min.css?ver=5.15.3 | B23: =IFERROR(__xludf.DUMMYFUNCTION("REGEXREPLACE(A23, ""^https?://[^/]+"", """")"),"/wp-content/plugins/elementor/assets/lib/font-awesome/css/fontawesome.min.css?ver=5.15.3") -> /wp-content/plugins/elementor/assets/lib/font-awesome/css/fontawesome.min.css?ver=5.15.3 | F23: text/css | G23: 200 | H23: OK | I23: Indexable | L23: 0 | M23: 0 | O23: 0 | P23: 0 | R23: 0 | S23: 0 | U23: 0 | W23: 0 | Y23: 0 | AA23: 0 | AC23: 0 | AM23: 12617 | AN23: 12617 | AO23: 12617 | AP23: 4.833 | AR23: 0 | AW23: 0 | AX23: 1 | AY23: 7 | BA23: 0 | BB23: 0 | BC23: 0 | BD23: 0 | BE23: 0 | BF23: 0 | BG23: 0 | BH23: 0 | BI23: 0 | BJ23: 0 | BP23: 0.265 | BQ23: Fri, 02 Jan 2026 17:29:45 GMT | BV23: 1.1 | EQ23: https://salesxceleration.com/wp-content/plugins/elementor/assets/lib/font-awesome/css/fontawesome.min.css?ver=5.15.3 | ER23: 46045.298
