Workbook

Sheet Current Pages
A1: CURRENT IL PAGES (NO BLOGS)
A2: https://www.sterlinglawyers.com/illinois/
A3: https://www.sterlinglawyers.com/illinois/divorce/
A4: https://www.sterlinglawyers.com/illinois/paternity/
A5: https://www.sterlinglawyers.com/illinois/child-custody/
A6: https://www.sterlinglawyers.com/illinois/attorneys/
A7: https://www.sterlinglawyers.com/illinois/locations/
A8: https://www.sterlinglawyers.com/illinois/pricing/
A9: https://www.sterlinglawyers.com/illinois/guardianship/
A10: https://www.sterlinglawyers.com/illinois/child-support/
A11: https://www.sterlinglawyers.com/illinois/property-division/
A12: https://www.sterlinglawyers.com/illinois/spousal-support/
... A229: https://www.sterlinglawyers.com/illinois/property-division/survivorship-marital-property/

Sheet Sterling_Lawyers_IL_Content_Gap
A1: Map ID | B1: Content Phase | C1: Content Category | D1: Content Type | E1: Content Role | F1: Page Title Structure | G1: Idealized URL | H1: Target Seed Keyword | I1: Existing Client URL | J1: Gap Status | K1: Notes | L1: -
A2: AH (Attorney Hub) | B2: Phase 1 | C2: Firm Hub | D2: Attorney Directory | E2: Navigation + Trust | F2: Illinois Family Law Attorneys | Sterling Lawyers | G2: https://www.sterlinglawyers.com/illinois/attorneys/ | H2: Illinois family law attorneys | I2: https://www.sterlinglawyers.com/illinois/attorneys/ | J2: MAPPED | K2: Attorney directory / hub page. Full match to existing page.
A3: LH (Location Hub) | B3: Phase 1 | C3: Firm Hub | D3: Location Directory | E3: Navigation + Trust | F3: Illinois Family Law Office Locations | Sterling Lawyers | G3: https://www.sterlinglawyers.com/illinois/locations/ | H3: Illinois family law office locations | I3: https://www.sterlinglawyers.com/illinois/locations/ | J3: MAPPED | K3: Location directory / hub page. Full match to existing page.
A4: 1 | B4: Phase 1 | C4: Practice Area | D4: Practice Area Hub | E4: Pillar Hub | F4: Illinois Divorce Lawyer | Sterling Lawyers | G4: https://www.sterlinglawyers.com/illinois/divorce/ | H4: illinois divorce lawyer | I4: https://www.sterlinglawyers.com/illinois/divorce/ | J4: MAPPED | K4: Full match to existing page.
A5: 2 | B5: Phase 1 | C5: Practice Area | D5: Practice Area Hub | E5: Pillar Hub | F5: Illinois Child Custody Lawyer | Sterling Lawyers | G5: https://www.sterlinglawyers.com/illinois/child-custody/ | H5: illinois child custody lawyer | I5: https://www.sterlinglawyers.com/illinois/child-custody/ | J5: MAPPED | K5: Full match to existing page.
A6: 3 | B6: Phase 1 | C6: Practice Area | D6: Practice Area Hub | E6: Pillar Hub | F6: Illinois Child Support Lawyer | Sterling Lawyers | G6: https://www.sterlinglawyers.com/illinois/child-support/ | H6: illinois child support lawyer | I6: https://www.sterlinglawyers.com/illinois/child-support/ | J6: MAPPED | K6: Full match to existing page.
A7: 4 | B7: Phase 1 | C7: Practice Area | D7: Practice Area Hub | E7: Pillar Hub | F7: Illinois Alimony Lawyer | Sterling Lawyers | G7: https://www.sterlinglawyers.com/illinois/spousal-support/ | H7: illinois alimony lawyer | I7: https://www.sterlinglawyers.com/illinois/spousal-support/ | J7: MAPPED | K7: Illinois uses 'spousal support' terminology; treat as alimony equivalent. Full match to existing page.
A8: 5 | B8: Phase 1 | C8: Practice Area | D8: Practice Area Hub | E8: Pillar Hub | F8: Illinois Property Division Lawyer | Sterling Lawyers | G8: https://www.sterlinglawyers.com/illinois/property-division/ | H8: illinois property division lawyer | I8: https://www.sterlinglawyers.com/illinois/property-division/ | J8: MAPPED | K8: Full match to existing page.
A9: 6 | B9: Phase 1 | C9: Practice Area | D9: Practice Area Hub | E9: Pillar Hub | F9: Illinois Paternity Lawyer | Sterling Lawyers | G9: https://www.sterlinglawyers.com/illinois/paternity/ | H9: illinois paternity lawyer | I9: https://www.sterlinglawyers.com/illinois/paternity/ | J9: MAPPED | K9: Paternity content also exists under Child Custody section. Full match to existing page.
A10: 7 | B10: Phase 1 | C10: Practice Area | D10: Practice Area Hub | E10: Pillar Hub | F10: Illinois Guardianship Lawyer | Sterling Lawyers | G10: https://www.sterlinglawyers.com/illinois/guardianship/ | H10: illinois guardianship lawyer | I10: https://www.sterlinglawyers.com/illinois/guardianship/ | J10: MAPPED | K10: Full match to existing page.
A11: 8 | B11: Phase 1 | C11: Procedural | D11: Process Page | E11: Cluster Support | F11: Contested Divorce in Illinois | Sterling Lawyers | G11: https://www.sterlinglawyers.com/illinois/divorce/contested/ | H11: illinois contested divorce | I11: https://www.sterlinglawyers.com/illinois/divorce/contested/ | J11: MAPPED | K11: Full match to existing page.
A12: 9 | B12: Phase 1 | C12: Procedural | D12: Process Page | E12: Cluster Support | F12: Uncontested Divorce in Illinois | Sterling Lawyers | G12: https://www.sterlinglawyers.com/illinois/divorce/uncontested-divorce/ | H12: illinois uncontested divorce | I12: https://www.sterlinglawyers.com/illinois/divorce/uncontested-divorce/ | J12: MAPPED | K12: Full match to existing page.
A13: 10 | B13: Phase 2 | C13: Procedural | D13: Process Page | E13: Cluster Support | F13: Child Custody Modification in Illinois | Sterling Lawyers | G13: https://www.sterlinglawyers.com/illinois/child-custody/modify-orders/ | H13: illinois child custody modification | I13: https://www.sterlinglawyers.com/illinois/child-custody/modify-orders/ | J13: MAPPED | K13: Full match to existing page.
A14: 11 | B14: Phase 2 | C14: Procedural | D14: Process Page | E14: Cluster Support | F14: Child Support Modification in Illinois | Sterling Lawyers | G14: https://www.sterlinglawyers.com/illinois/child-support/modify-orders/ | H14: illinois child support modification | I14: https://www.sterlinglawyers.com/illinois/child-support/modify-orders/ | J14: MAPPED | K14: Full match to existing page.
A15: 12 | B15: Phase 2 | C15: Procedural | D15: Process Page | E15: Cluster Support | F15: Child Support Enforcement in Illinois | Sterling Lawyers | G15: https://www.sterlinglawyers.com/illinois/child-support/enforce-orders/ | H15: illinois child support enforcement | I15: https://www.sterlinglawyers.com/illinois/child-support/enforce-orders/ | J15: MAPPED | K15: Full match to existing page.
... A23: 20 | B23: Phase 2 | C23: Procedural | D23: Process Page | E23: Cluster Support | F23: Guardianship of a Minor in Illinois | Sterling Lawyers | G23: https://www.sterlinglawyers.com/illinois/guardianship/minor/ | H23: illinois guardianship of a minor | I23: https://www.sterlinglawyers.com/illinois/guardianship/ | J23: PARTIAL | K23: Guardianship hub appears to focus on minors; no dedicated minor-only page. Partial coverage via https://www.sterlinglawyers.com/illinois/guardianship/ — recommend dedicated page at https://www.sterlinglawyers.com/illinois/guardianship/minor/.
A24: 21 | B24: Phase 2 | C24: Procedural | D24: Process Page | E24: Cluster Support | F24: Adult Guardianship in Illinois | Sterling Lawyers | G24: https://www.sterlinglawyers.com/illinois/guardianship/adult/ | H24: illinois adult guardianship | J24: GAP - MISSING | K24: No adult guardianship content detected; guardianship hub appears focused on minors. No dedicated page found — create at https://www.sterlinglawyers.com/illinois/guardianship/adult/.
A25: 22 | B25: Phase 2 | C25: Procedural | D25: Process Page | E25: Cluster Support | F25: Challenging Paternity in Illinois | Sterling Lawyers | G25: https://www.sterlinglawyers.com/illinois/paternity/challenging-paternity/ | H25: illinois challenging paternity | J25: GAP - MISSING | K25: No paternity challenge/disestablishment page detected. No dedicated page found — create at https://www.sterlinglawyers.com/illinois/paternity/challenging-paternity/.
A26: 23 | B26: Phase 2 | C26: Procedural | D26: Process Page | E26: Cluster Support | F26: Legal Separation in Illinois | Sterling Lawyers | G26: https://www.sterlinglawyers.com/illinois/divorce/separation/ | H26: illinois legal separation | I26: https://www.sterlinglawyers.com/illinois/divorce/separation/ | J26: MAPPED | K26: Full match to existing page.
A27: 24 | B27: Phase 2 | C27: Procedural | D27: Process Page | E27: Cluster Support | F27: Divorce Mediation in Illinois | Sterling Lawyers | G27: https://www.sterlinglawyers.com/illinois/divorce/mediation/ | H27: illinois divorce mediation | I27: https://www.sterlinglawyers.com/illinois/divorce/mediation/ | J27: MAPPED | K27: Full match to existing page.
A28: 25 | B28: Phase 2 | C28: Procedural | D28: Process Page | E28: Cluster Support | F28: Collaborative Divorce in Illinois | Sterling Lawyers | G28: https://www.sterlinglawyers.com/illinois/divorce/collaborative/ | H28: illinois collaborative divorce | I28: https://www.sterlinglawyers.com/illinois/divorce/collaborative/ | J28: MAPPED | K28: Full match to existing page.
A29: 26 | B29: Phase 2 | C29: Procedural | D29: Process Page | E29: Cluster Support | F29: Temporary Guardianship in Illinois | Sterling Lawyers | G29: https://www.sterlinglawyers.com/illinois/guardianship/temporary/ | H29: illinois temporary guardianship | J29: GAP - MISSING | K29: No temporary guardianship page detected. No dedicated page found — create at https://www.sterlinglawyers.com/illinois/guardianship/temporary/.
A30: 27 | B30: Phase 3 | C30: Situational | D30: Situation Page | E30: Cluster Support | F30: High-Conflict Divorce in Illinois | Sterling Lawyers | G30: https://www.sterlinglawyers.com/illinois/divorce/high-conflict/ | H30: illinois high-conflict divorce | I30: https://www.sterlinglawyers.com/illinois/divorce/litigation/ | J30: PARTIAL | K30: Litigation / protective orders likely capture high-conflict intent. Partial coverage via https://www.sterlinglawyers.com/illinois/divorce/litigation/ — recommend dedicated page at https://www.sterlinglawyers.com/illinois/divorce/high-conflict/.
A31: 28 | B31: Phase 3 | C31: Situational | D31: Situation Page | E31: Cluster Support | F31: Relocation / Move-Away Custody Disputes in Illinois | Sterling Lawyers | G31: https://www.sterlinglawyers.com/illinois/child-custody/relocation/ | H31: illinois relocation / move-away custody disputes | I31: https://www.sterlinglawyers.com/illinois/child-custody/ | J31: PARTIAL | K31: Relocation appears addressed within custody/parenting plan content; no dedicated relocation dispute page. Partial coverage via https://www.sterlinglawyers.com/illinois/child-custody/ — recommend dedicated page at https://www.sterlinglawyers.com/illinois/child-custody/relocation/.
A32: 29 | B32: Phase 3 | C32: Situational | D32: Situation Page | E32: Cluster Support | F32: Divorce Involving Business Ownership in Illinois | Sterling Lawyers | G32: https://www.sterlinglawyers.com/illinois/divorce/business-ownership/ | H32: illinois divorce involving business ownership | J32: GAP - MISSING | K32: No business ownership divorce page detected. No dedicated page found — create at https://www.sterlinglawyers.com/illinois/divorce/business-ownership/.
A33: 30 | B33: Phase 3 | C33: Situational | D33: Situation Page | E33: Cluster Support | F33: High-Conflict Custody in Illinois | Sterling Lawyers | G33: https://www.sterlinglawyers.com/illinois/child-custody/high-conflict/ | H33: illinois high-conflict custody | I33: https://www.sterlinglawyers.com/illinois/child-custody/parental-alienation/ | J33: PARTIAL | K33: Covered partially via alienation/narcissist co-parenting pages. Partial coverage via https://www.sterlinglawyers.com/illinois/child-custody/parental-alienation/ — recommend dedicated page at https://www.sterlinglawyers.com/illinois/child-custody/high-conflict/.
A34: 31 | B34: Phase 3 | C34: Situational | D34: Situation Page | E34: Cluster Support | F34: Child Support Disputes After Income Changes in Illinois | Sterling Lawyers | G34: https://www.sterlinglawyers.com/illinois/child-support/income-change/ | H34: illinois child support disputes after income changes | I34: https://www.sterlinglawyers.com/illinois/child-support/modify-orders/ | J34: PARTIAL | K34: Modification page covers income change scenarios; no dedicated income-change dispute page. Partial coverage via https://www.sterlinglawyers.com/illinois/child-support/modify-orders/ — recommend dedicated page at https://www.sterlinglawyers.com/illinois/child-support/income-change/.
A35: 32 | B35: Phase 3 | C35: Situational | D35: Situation Page | E35: Cluster Support | F35: Back Child Support / Arrears in Illinois | Sterling Lawyers | G35: https://www.sterlinglawyers.com/illinois/child-support/arrears/ | H35: illinois back child support / arrears | I35: https://www.sterlinglawyers.com/illinois/child-support/enforce-orders/ | J35: PARTIAL | K35: Enforcement page likely touches arrears; no arrears-focused page detected. Partial coverage via https://www.sterlinglawyers.com/illinois/child-support/enforce-orders/ — recommend dedicated page at https://www.sterlinglawyers.com/illinois/child-support/arrears/.
A36: 33 | B36: Phase 3 | C36: Situational | D36: Situation Page | E36: Cluster Support | F36: Long-Term Marriage Divorce in Illinois | Sterling Lawyers | G36: https://www.sterlinglawyers.com/illinois/divorce/long-term-marriage/ | H36: illinois long-term marriage divorce | J36: GAP - MISSING | K36: No long-term marriage divorce page detected. No dedicated page found — create at https://www.sterlinglawyers.com/illinois/divorce/long-term-marriage/.
A37: 34 | B37: Phase 3 | C37: Situational | D37: Situation Page | E37: Cluster Support | F37: Business Valuation and Division in Illinois | Sterling Lawyers | G37: https://www.sterlinglawyers.com/illinois/property-division/business-valuation/ | H37: illinois business valuation and division | J37: GAP - MISSING | K37: No business valuation page detected. No dedicated page found — create at https://www.sterlinglawyers.com/illinois/property-division/business-valuation/.
A38: 35 | B38: Phase 3 | C38: Situational | D38: Situation Page | E38: Cluster Support | F38: Emergency Guardianship in Illinois | Sterling Lawyers | G38: https://www.sterlinglawyers.com/illinois/guardianship/emergency/ | H38: illinois emergency guardianship | J38: GAP - MISSING | K38: No emergency guardianship page detected. No dedicated page found — create at https://www.sterlinglawyers.com/illinois/guardianship/emergency/.
A39: 36 | B39: Phase 3 | C39: Situational | D39: Situation Page | E39: Cluster Support | F39: Parenting Time Disputes in Illinois | Sterling Lawyers | G39: https://www.sterlinglawyers.com/illinois/child-custody/parenting-time-disputes/ | H39: illinois parenting time disputes | I39: https://www.sterlinglawyers.com/illinois/child-custody/split-orders/ | J39: PARTIAL | K39: Split/enforcement pages partially address parenting time disputes. Partial coverage via https://www.sterlinglawyers.com/illinois/child-custody/split-orders/ — recommend dedicated page at https://www.sterlinglawyers.com/illinois/child-custody/parenting-time-disputes/.
A40: 37 | B40: Phase 3 | C40: Situational | D40: Situation Page | E40: Cluster Support | F40: High-Income Spousal Support Disputes in Illinois | Sterling Lawyers | G40: https://www.sterlinglawyers.com/illinois/spousal-support/high-income/ | H40: illinois high-income spousal support disputes | J40: GAP - MISSING | K40: No high-income spousal support dispute content detected. No dedicated page found — create at https://www.sterlinglawyers.com/illinois/spousal-support/high-income/.
A41: 38 | B41: Phase 3 | C41: Situational | D41: Situation Page | E41: Cluster Support | F41: Self-Employed or Variable Income Support in Illinois | Sterling Lawyers | G41: https://www.sterlinglawyers.com/illinois/child-support/self-employed-income/ | H41: illinois self-employed or variable income support | J41: GAP - MISSING | K41: No self-employed/variable income support page detected. No dedicated page found — create at https://www.sterlinglawyers.com/illinois/child-support/self-employed-income/.
A42: 39 | B42: Phase 3 | C42: Situational | D42: Situation Page | E42: Cluster Support | F42: Supervised Visitation in Illinois | Sterling Lawyers | G42: https://www.sterlinglawyers.com/illinois/child-custody/supervised-visitation/ | H42: illinois supervised visitation | J42: GAP - MISSING | K42: No supervised visitation page detected. No dedicated page found — create at https://www.sterlinglawyers.com/illinois/child-custody/supervised-visitation/.
A43: 40 | B43: Phase 3 | C43: Situational | D43: Situation Page | E43: Cluster Support | F43: Hidden Assets and Financial Misconduct in Illinois | Sterling Lawyers | G43: https://www.sterlinglawyers.com/illinois/property-division/hidden-assets/ | H43: illinois hidden assets and financial misconduct | I43: https://www.sterlinglawyers.com/illinois/property-division/hidden-assets/ | J43: MAPPED | K43: Full match to existing page.

Sheet Performance Summary
A1: Map ID | B1: Page Title | C1: Target Keyword | D1: URL | F1: Status Code | G1: L3M Clicks | H1: Prev 3M Clicks | I1: Δ Clicks % | J1: L3M Impressions | K1: Prev 3M Impressions | L1: Δ Impr % | M1: L3M New Users | N1: Prev 3M New Users | O1: Δ Users % | P1: L3M Key Events | Q1: Prev 3M Key Events | R1: Δ Conv %
A2: 1 | B2: Attorney Hub | C2: family law attorneys texas | D2: https://sbrownlawyer.com/attorneys/ | E2: /attorneys | F2: =vlookup(D2,L3m_search_console_all!A:B,2,0) -> 200 | G2: =vlookup(D2,L3m_search_console_all!A:F,6,0) -> 57 | H2: =vlookup(D2,P3m_search_console!A:F,6,0) -> 101 | I2: =IF(H2>0,(G2-H2)/H2,"N/A") -> -0.43564356 | J2: =vlookup(D2,L3m_search_console_all!A:G,7,0) -> 19373 | K2: =vlookup(D2,P3m_search_console!A:G,7,0) -> 34633 | L2: =IF(K2>0,(J2-K2)/K2,"N/A") -> -0.44062022 | M2: =vlookup(D2,L3m_analytics_all!A:M,13,0) -> 71 | N2: =vlookup(E2,P3M_analytics!A:D,4,0) -> 125 | O2: =IF(N2>0,(M2-N2)/N2,"N/A") -> -0.432 | P2: =vlookup(D2,L3m_analytics_all!A:J,10,0) -> 0 | Q2: =vlookup(E2,P3M_analytics!A:F,6,0) -> 11 | R2: =IF(Q2>0,(P2-Q2)/Q2,"N/A") -> -1
A3: 2 | B3: Location Hub | C3: family law office locations texas | D3: https://sbrownlawyer.com/texas/locations/ | E3: /texas/locations | F3: =vlookup(D3,L3m_search_console_all!A:B,2,0) -> 200 | G3: =vlookup(D3,L3m_search_console_all!A:F,6,0) -> 2 | H3: =vlookup(D3,P3m_search_console!A:F,6,0) -> 0 | I3: =IF(H3>0,(G3-H3)/H3,"N/A") -> N/A | J3: =vlookup(D3,L3m_search_console_all!A:G,7,0) -> 1703 | K3: =vlookup(D3,P3m_search_console!A:G,7,0) -> 300 | L3: =IF(K3>0,(J3-K3)/K3,"N/A") -> 4.6766667 | M3: =vlookup(D3,L3m_analytics_all!A:M,13,0) -> 8 | N3: =vlookup(E3,P3M_analytics!A:D,4,0) -> 11 | O3: =IF(N3>0,(M3-N3)/N3,"N/A") -> -0.27272727 | P3: =vlookup(D3,L3m_analytics_all!A:J,10,0) -> 1 | Q3: =vlookup(E3,P3M_analytics!A:F,6,0) -> 0 | R3: =IF(Q3>0,(P3-Q3)/Q3,"N/A") -> N/A
A4: 3 | B4: Divorce Hub | C4: divorce lawyer texas | D4: https://sbrownlawyer.com/divorce/ | E4: /divorce | F4: =vlookup(D4,L3m_search_console_all!A:B,2,0) -> 200 | G4: =vlookup(D4,L3m_search_console_all!A:F,6,0) -> 7 | H4: =vlookup(D4,P3m_search_console!A:F,6,0) -> 24 | I4: =IF(H4>0,(G4-H4)/H4,"N/A") -> -0.70833333 | J4: =vlookup(D4,L3m_search_console_all!A:G,7,0) -> 12101 | K4: =vlookup(D4,P3m_search_console!A:G,7,0) -> 18218 | L4: =IF(K4>0,(J4-K4)/K4,"N/A") -> -0.33576682 | M4: =vlookup(D4,L3m_analytics_all!A:M,13,0) -> 13 | N4: =vlookup(E4,P3M_analytics!A:D,4,0) -> 32 | O4: =IF(N4>0,(M4-N4)/N4,"N/A") -> -0.59375 | P4: =vlookup(D4,L3m_analytics_all!A:J,10,0) -> 0 | Q4: =vlookup(E4,P3M_analytics!A:F,6,0) -> 1 | R4: =IF(Q4>0,(P4-Q4)/Q4,"N/A") -> -1
A5: 4 | B5: Child Custody Hub | C5: child custody lawyer texas | D5: https://sbrownlawyer.com/child-custody/ | E5: /child-custody | F5: =vlookup(D5,L3m_search_console_all!A:B,2,0) -> 200 | G5: =vlookup(D5,L3m_search_console_all!A:F,6,0) -> 2 | H5: =vlookup(D5,P3m_search_console!A:F,6,0) -> 9 | I5: =IF(H5>0,(G5-H5)/H5,"N/A") -> -0.77777778 | J5: =vlookup(D5,L3m_search_console_all!A:G,7,0) -> 3310 | K5: =vlookup(D5,P3m_search_console!A:G,7,0) -> 28578 | L5: =IF(K5>0,(J5-K5)/K5,"N/A") -> -0.88417664 | M5: =vlookup(D5,L3m_analytics_all!A:M,13,0) -> 5 | N5: =vlookup(E5,P3M_analytics!A:D,4,0) -> 11 | O5: =IF(N5>0,(M5-N5)/N5,"N/A") -> -0.54545455 | P5: =vlookup(D5,L3m_analytics_all!A:J,10,0) -> 1 | Q5: =vlookup(E5,P3M_analytics!A:F,6,0) -> 0 | R5: =IF(Q5>0,(P5-Q5)/Q5,"N/A") -> N/A
A6: 5 | B6: Child Support Hub | C6: child support lawyer texas | D6: https://sbrownlawyer.com/child-support/ | E6: /child-support | F6: =vlookup(D6,L3m_search_console_all!A:B,2,0) -> 200 | G6: =vlookup(D6,L3m_search_console_all!A:F,6,0) -> 1 | H6: =vlookup(D6,P3m_search_console!A:F,6,0) -> 1 | I6: =IF(H6>0,(G6-H6)/H6,"N/A") -> 0 | J6: =vlookup(D6,L3m_search_console_all!A:G,7,0) -> 2110 | K6: =vlookup(D6,P3m_search_console!A:G,7,0) -> 4643 | L6: =IF(K6>0,(J6-K6)/K6,"N/A") -> -0.54555244 | M6: =vlookup(D6,L3m_analytics_all!A:M,13,0) -> 3 | N6: =vlookup(E6,P3M_analytics!A:D,4,0) -> 6 | O6: =IF(N6>0,(M6-N6)/N6,"N/A") -> -0.5 | P6: =vlookup(D6,L3m_analytics_all!A:J,10,0) -> 1 | Q6: =vlookup(E6,P3M_analytics!A:F,6,0) -> 0 | R6: =IF(Q6>0,(P6-Q6)/Q6,"N/A") -> N/A
A7: 6 | B7: Spousal Support / Alimony Hub | C7: alimony lawyer texas | D7: https://sbrownlawyer.com/attorneys-working-to-achieve-your-alimony-goals/ | E7: /attorneys-working-to-achieve-your-alimony-goals | F7: =vlookup(D7,L3m_search_console_all!A:B,2,0) -> 200 | G7: =vlookup(D7,L3m_search_console_all!A:F,6,0) -> 0 | H7: =vlookup(D7,P3m_search_console!A:F,6,0) -> 3 | I7: =IF(H7>0,(G7-H7)/H7,"N/A") -> -1 | J7: =vlookup(D7,L3m_search_console_all!A:G,7,0) -> 535 | K7: =vlookup(D7,P3m_search_console!A:G,7,0) -> 1731 | L7: =IF(K7>0,(J7-K7)/K7,"N/A") -> -0.6909301 | M7: =vlookup(D7,L3m_analytics_all!A:M,13,0) -> 1 | N7: =vlookup(E7,P3M_analytics!A:D,4,0) -> 2 | O7: =IF(N7>0,(M7-N7)/N7,"N/A") -> -0.5 | P7: =vlookup(D7,L3m_analytics_all!A:J,10,0) -> 0 | Q7: =vlookup(E7,P3M_analytics!A:F,6,0) -> 0 | R7: =IF(Q7>0,(P7-Q7)/Q7,"N/A") -> N/A
A8: 7 | B8: Property Division Hub | C8: property division lawyer texas | D8: https://sbrownlawyer.com/division-of-property/ | E8: /division-of-property | F8: =vlookup(D8,L3m_search_console_all!A:B,2,0) -> 200 | G8: =vlookup(D8,L3m_search_console_all!A:F,6,0) -> 2 | H8: =vlookup(D8,P3m_search_console!A:F,6,0) -> 5 | I8: =IF(H8>0,(G8-H8)/H8,"N/A") -> -0.6 | J8: =vlookup(D8,L3m_search_console_all!A:G,7,0) -> 499 | K8: =vlookup(D8,P3m_search_console!A:G,7,0) -> 577 | L8: =IF(K8>0,(J8-K8)/K8,"N/A") -> -0.13518198 | M8: =vlookup(D8,L3m_analytics_all!A:M,13,0) -> 4 | N8: =vlookup(E8,P3M_analytics!A:D,4,0) -> 5 | O8: =IF(N8>0,(M8-N8)/N8,"N/A") -> -0.2 | P8: =vlookup(D8,L3m_analytics_all!A:J,10,0) -> 0 | Q8: =vlookup(E8,P3M_analytics!A:F,6,0) -> 0 | R8: =IF(Q8>0,(P8-Q8)/Q8,"N/A") -> N/A
A9: 8 | B9: Paternity Hub | C9: paternity lawyer texas | D9: https://sbrownlawyer.com/paternity/ | E9: /paternity | F9: =vlookup(D9,L3m_search_console_all!A:B,2,0) -> 200 | G9: =vlookup(D9,L3m_search_console_all!A:F,6,0) -> 0 | H9: =vlookup(D9,P3m_search_console!A:F,6,0) -> 0 | I9: =IF(H9>0,(G9-H9)/H9,"N/A") -> N/A | J9: =vlookup(D9,L3m_search_console_all!A:G,7,0) -> 112 | K9: =vlookup(D9,P3m_search_console!A:G,7,0) -> 356 | L9: =IF(K9>0,(J9-K9)/K9,"N/A") -> -0.68539326 | M9: =vlookup(D9,L3m_analytics_all!A:M,13,0) -> 1 | N9: =vlookup(E9,P3M_analytics!A:D,4,0) -> 1 | O9: =IF(N9>0,(M9-N9)/N9,"N/A") -> 0 | P9: =vlookup(D9,L3m_analytics_all!A:J,10,0) -> 0 | Q9: =vlookup(E9,P3M_analytics!A:F,6,0) -> 0 | R9: =IF(Q9>0,(P9-Q9)/Q9,"N/A") -> N/A
A10: 10 | B10: Contested Divorce | C10: contested divorce texas | D10: https://sbrownlawyer.com/complex-and-contested-divorce-attorneys/ | E10: /complex-and-contested-divorce-attorneys | F10: =vlookup(D10,L3m_search_console_all!A:B,2,0) -> 200 | G10: =vlookup(D10,L3m_search_console_all!A:F,6,0) -> 0 | H10: =vlookup(D10,P3m_search_console!A:F,6,0) -> 0 | I10: =IF(H10>0,(G10-H10)/H10,"N/A") -> N/A | J10: =vlookup(D10,L3m_search_console_all!A:G,7,0) -> 58 | K10: =vlookup(D10,P3m_search_console!A:G,7,0) -> 16 | L10: =IF(K10>0,(J10-K10)/K10,"N/A") -> 2.625 | M10: =vlookup(D10,L3m_analytics_all!A:M,13,0) -> 1 | N10: =vlookup(E10,P3M_analytics!A:D,4,0) -> #N/A | O10: =IF(N10>0,(M10-N10)/N10,"N/A") -> #N/A | P10: =vlookup(D10,L3m_analytics_all!A:J,10,0) -> 0 | Q10: =vlookup(E10,P3M_analytics!A:F,6,0) -> #N/A | R10: =IF(Q10>0,(P10-Q10)/Q10,"N/A") -> #N/A
A11: 11 | B11: Uncontested Divorce | C11: uncontested divorce texas | D11: https://sbrownlawyer.com/uncontested-divorce-lawyer-in-pearland/ | E11: /uncontested-divorce-lawyer-in-pearland | F11: =vlookup(D11,L3m_search_console_all!A:B,2,0) -> 200 | G11: =vlookup(D11,L3m_search_console_all!A:F,6,0) -> 4 | H11: =vlookup(D11,P3m_search_console!A:F,6,0) -> 7 | I11: =IF(H11>0,(G11-H11)/H11,"N/A") -> -0.42857143 | J11: =vlookup(D11,L3m_search_console_all!A:G,7,0) -> 1454 | K11: =vlookup(D11,P3m_search_console!A:G,7,0) -> 1754 | L11: =IF(K11>0,(J11-K11)/K11,"N/A") -> -0.17103763 | M11: =vlookup(D11,L3m_analytics_all!A:M,13,0) -> 6 | N11: =vlookup(E11,P3M_analytics!A:D,4,0) -> 4 | O11: =IF(N11>0,(M11-N11)/N11,"N/A") -> 0.5 | P11: =vlookup(D11,L3m_analytics_all!A:J,10,0) -> 1 | Q11: =vlookup(E11,P3M_analytics!A:F,6,0) -> 0 | R11: =IF(Q11>0,(P11-Q11)/Q11,"N/A") -> N/A
A12: 12 | B12: Child Custody Modification | C12: child custody modification texas | D12: https://sbrownlawyer.com/modification-of-custody/ | E12: /modification-of-custody | F12: =vlookup(D12,L3m_search_console_all!A:B,2,0) -> 200 | G12: =vlookup(D12,L3m_search_console_all!A:F,6,0) -> 1 | H12: =vlookup(D12,P3m_search_console!A:F,6,0) -> 0 | I12: =IF(H12>0,(G12-H12)/H12,"N/A") -> N/A | J12: =vlookup(D12,L3m_search_console_all!A:G,7,0) -> 475 | K12: =vlookup(D12,P3m_search_console!A:G,7,0) -> 563 | L12: =IF(K12>0,(J12-K12)/K12,"N/A") -> -0.15630551 | M12: =vlookup(D12,L3m_analytics_all!A:M,13,0) -> 1 | N12: =vlookup(E12,P3M_analytics!A:D,4,0) -> #N/A | O12: =IF(N12>0,(M12-N12)/N12,"N/A") -> #N/A | P12: =vlookup(D12,L3m_analytics_all!A:J,10,0) -> 0 | Q12: =vlookup(E12,P3M_analytics!A:F,6,0) -> #N/A | R12: =IF(Q12>0,(P12-Q12)/Q12,"N/A") -> #N/A
A13: 13 | B13: Child Support Modification | C13: child support modification texas | D13: https://sbrownlawyer.com/child-support-modifications/ | E13: /child-support-modifications | F13: =vlookup(D13,L3m_search_console_all!A:B,2,0) -> 200 | G13: =vlookup(D13,L3m_search_console_all!A:F,6,0) -> 0 | H13: =vlookup(D13,P3m_search_console!A:F,6,0) -> 0 | I13: =IF(H13>0,(G13-H13)/H13,"N/A") -> N/A | J13: =vlookup(D13,L3m_search_console_all!A:G,7,0) -> 193 | K13: =vlookup(D13,P3m_search_console!A:G,7,0) -> 514 | L13: =IF(K13>0,(J13-K13)/K13,"N/A") -> -0.62451362 | M13: =vlookup(D13,L3m_analytics_all!A:M,13,0) | N13: =vlookup(E13,P3M_analytics!A:D,4,0) -> 2 | O13: =IF(N13>0,(M13-N13)/N13,"N/A") -> -1 | P13: =vlookup(D13,L3m_analytics_all!A:J,10,0) | Q13: =vlookup(E13,P3M_analytics!A:F,6,0) -> 0 | R13: =IF(Q13>0,(P13-Q13)/Q13,"N/A") -> N/A
... A28: 42 | B28: Hidden Assets and Financial Misconduct | C28: hidden assets divorce texas | D28: https://sbrownlawyer.com/hidden-assets/ | E28: /hidden-assets | F28: =vlookup(D28,L3m_search_console_all!A:B,2,0) -> 200 | G28: =vlookup(D28,L3m_search_console_all!A:F,6,0) -> 1 | H28: =vlookup(D28,P3m_search_console!A:F,6,0) -> 0 | I28: =IF(H28>0,(G28-H28)/H28,"N/A") -> N/A | J28: =vlookup(D28,L3m_search_console_all!A:G,7,0) -> 5 | K28: =vlookup(D28,P3m_search_console!A:G,7,0) -> 6 | L28: =IF(K28>0,(J28-K28)/K28,"N/A") -> -0.16666667 | M28: =vlookup(D28,L3m_analytics_all!A:M,13,0) -> 2 | N28: =vlookup(E28,P3M_analytics!A:D,4,0) -> #N/A | O28: =IF(N28>0,(M28-N28)/N28,"N/A") -> #N/A | P28: =vlookup(D28,L3m_analytics_all!A:J,10,0) -> 0 | Q28: =vlookup(E28,P3M_analytics!A:F,6,0) -> #N/A | R28: =IF(Q28>0,(P28-Q28)/Q28,"N/A") -> #N/A

Sheet YoY Comparison
A1: Map ID | B1: Page Title | C1: Target Keyword | D1: URL | E1: L3M Clicks | F1: L3M LY Clicks | G1: YoY Δ % | H1: L3M Impressions | I1: L3M LY Impressions | J1: YoY Δ %
A2: 1 | B2: Attorney Hub | C2: family law attorneys texas | D2: https://sbrownlawyer.com/attorneys/ | E2: =vlookup(D2,L3m_search_console_all!A:F,6,0) -> 57 | F2: =vlookup(D2,L3M_LY_search_console!A:B,2,0) -> 54 | G2: =IF(F2>0,(E2-F2)/F2,"N/A") -> 0.055555556 | H2: =vlookup(D2,L3m_search_console_all!A:G,7,0) -> 19373 | I2: =vlookup(D2,L3M_LY_search_console!A:C,3,0) -> 15958 | J2: =IF(I2>0,(H2-I2)/I2,"N/A") -> 0.21399925
A3: 2 | B3: Location Hub | C3: family law office locations texas | D3: https://sbrownlawyer.com/texas/locations/ | E3: =vlookup(D3,L3m_search_console_all!A:F,6,0) -> 2 | F3: =vlookup(D3,L3M_LY_search_console!A:B,2,0) -> #N/A | G3: =IF(F3>0,(E3-F3)/F3,"N/A") -> #N/A | H3: =vlookup(D3,L3m_search_console_all!A:G,7,0) -> 1703 | I3: =vlookup(D3,L3M_LY_search_console!A:C,3,0) -> #N/A | J3: =IF(I3>0,(H3-I3)/I3,"N/A") -> #N/A
A4: 3 | B4: Divorce Hub | C4: divorce lawyer texas | D4: https://sbrownlawyer.com/divorce/ | E4: =vlookup(D4,L3m_search_console_all!A:F,6,0) -> 7 | F4: =vlookup(D4,L3M_LY_search_console!A:B,2,0) -> 29 | G4: =IF(F4>0,(E4-F4)/F4,"N/A") -> -0.75862069 | H4: =vlookup(D4,L3m_search_console_all!A:G,7,0) -> 12101 | I4: =vlookup(D4,L3M_LY_search_console!A:C,3,0) -> 16016 | J4: =IF(I4>0,(H4-I4)/I4,"N/A") -> -0.24444306
A5: 4 | B5: Child Custody Hub | C5: child custody lawyer texas | D5: https://sbrownlawyer.com/child-custody/ | E5: =vlookup(D5,L3m_search_console_all!A:F,6,0) -> 2 | F5: =vlookup(D5,L3M_LY_search_console!A:B,2,0) -> 2 | G5: =IF(F5>0,(E5-F5)/F5,"N/A") -> 0 | H5: =vlookup(D5,L3m_search_console_all!A:G,7,0) -> 3310 | I5: =vlookup(D5,L3M_LY_search_console!A:C,3,0) -> 8796 | J5: =IF(I5>0,(H5-I5)/I5,"N/A") -> -0.62369259
A6: 5 | B6: Child Support Hub | C6: child support lawyer texas | D6: https://sbrownlawyer.com/child-support/ | E6: =vlookup(D6,L3m_search_console_all!A:F,6,0) -> 1 | F6: =vlookup(D6,L3M_LY_search_console!A:B,2,0) -> 1 | G6: =IF(F6>0,(E6-F6)/F6,"N/A") -> 0 | H6: =vlookup(D6,L3m_search_console_all!A:G,7,0) -> 2110 | I6: =vlookup(D6,L3M_LY_search_console!A:C,3,0) -> 6838 | J6: =IF(I6>0,(H6-I6)/I6,"N/A") -> -0.69143024
A7: 6 | B7: Spousal Support / Alimony Hub | C7: alimony lawyer texas | D7: https://sbrownlawyer.com/attorneys-working-to-achieve-your-alimony-goals/ | E7: =vlookup(D7,L3m_search_console_all!A:F,6,0) -> 0 | F7: =vlookup(D7,L3M_LY_search_console!A:B,2,0) -> 0 | G7: =IF(F7>0,(E7-F7)/F7,"N/A") -> N/A | H7: =vlookup(D7,L3m_search_console_all!A:G,7,0) -> 535 | I7: =vlookup(D7,L3M_LY_search_console!A:C,3,0) -> 892 | J7: =IF(I7>0,(H7-I7)/I7,"N/A") -> -0.40022422
A8: 7 | B8: Property Division Hub | C8: property division lawyer texas | D8: https://sbrownlawyer.com/division-of-property/ | E8: =vlookup(D8,L3m_search_console_all!A:F,6,0) -> 2 | F8: =vlookup(D8,L3M_LY_search_console!A:B,2,0) -> 6 | G8: =IF(F8>0,(E8-F8)/F8,"N/A") -> -0.66666667 | H8: =vlookup(D8,L3m_search_console_all!A:G,7,0) -> 499 | I8: =vlookup(D8,L3M_LY_search_console!A:C,3,0) -> 2126 | J8: =IF(I8>0,(H8-I8)/I8,"N/A") -> -0.76528692
A9: 8 | B9: Paternity Hub | C9: paternity lawyer texas | D9: https://sbrownlawyer.com/paternity/ | E9: =vlookup(D9,L3m_search_console_all!A:F,6,0) -> 0 | F9: =vlookup(D9,L3M_LY_search_console!A:B,2,0) -> 0 | G9: =IF(F9>0,(E9-F9)/F9,"N/A") -> N/A | H9: =vlookup(D9,L3m_search_console_all!A:G,7,0) -> 112 | I9: =vlookup(D9,L3M_LY_search_console!A:C,3,0) -> 476 | J9: =IF(I9>0,(H9-I9)/I9,"N/A") -> -0.76470588
A10: 10 | B10: Contested Divorce | C10: contested divorce texas | D10: https://sbrownlawyer.com/complex-and-contested-divorce-attorneys/ | E10: =vlookup(D10,L3m_search_console_all!A:F,6,0) -> 0 | F10: =vlookup(D10,L3M_LY_search_console!A:B,2,0) -> 0 | G10: =IF(F10>0,(E10-F10)/F10,"N/A") -> N/A | H10: =vlookup(D10,L3m_search_console_all!A:G,7,0) -> 58 | I10: =vlookup(D10,L3M_LY_search_console!A:C,3,0) -> 44 | J10: =IF(I10>0,(H10-I10)/I10,"N/A") -> 0.31818182
A11: 11 | B11: Uncontested Divorce | C11: uncontested divorce texas | D11: https://sbrownlawyer.com/uncontested-divorce-lawyer-in-pearland/ | E11: =vlookup(D11,L3m_search_console_all!A:F,6,0) -> 4 | F11: =vlookup(D11,L3M_LY_search_console!A:B,2,0) -> 8 | G11: =IF(F11>0,(E11-F11)/F11,"N/A") -> -0.5 | H11: =vlookup(D11,L3m_search_console_all!A:G,7,0) -> 1454 | I11: =vlookup(D11,L3M_LY_search_console!A:C,3,0) -> 3452 | J11: =IF(I11>0,(H11-I11)/I11,"N/A") -> -0.5787949
A12: 12 | B12: Child Custody Modification | C12: child custody modification texas | D12: https://sbrownlawyer.com/modification-of-custody/ | E12: =vlookup(D12,L3m_search_console_all!A:F,6,0) -> 1 | F12: =vlookup(D12,L3M_LY_search_console!A:B,2,0) -> 0 | G12: =IF(F12>0,(E12-F12)/F12,"N/A") -> N/A | H12: =vlookup(D12,L3m_search_console_all!A:G,7,0) -> 475 | I12: =vlookup(D12,L3M_LY_search_console!A:C,3,0) -> 396 | J12: =IF(I12>0,(H12-I12)/I12,"N/A") -> 0.19949495
A13: 13 | B13: Child Support Modification | C13: child support modification texas | D13: https://sbrownlawyer.com/child-support-modifications/ | E13: =vlookup(D13,L3m_search_console_all!A:F,6,0) -> 0 | F13: =vlookup(D13,L3M_LY_search_console!A:B,2,0) -> 0 | G13: =IF(F13>0,(E13-F13)/F13,"N/A") -> N/A | H13: =vlookup(D13,L3m_search_console_all!A:G,7,0) -> 193 | I13: =vlookup(D13,L3M_LY_search_console!A:C,3,0) -> 214 | J13: =IF(I13>0,(H13-I13)/I13,"N/A") -> -0.098130841
... A28: 42 | B28: Hidden Assets and Financial Misconduct | C28: hidden assets divorce texas | D28: https://sbrownlawyer.com/hidden-assets/ | E28: =vlookup(D28,L3m_search_console_all!A:F,6,0) -> 1 | F28: =vlookup(D28,L3M_LY_search_console!A:B,2,0) -> 0 | G28: =IF(F28>0,(E28-F28)/F28,"N/A") -> N/A | H28: =vlookup(D28,L3m_search_console_all!A:G,7,0) -> 5 | I28: =vlookup(D28,L3M_LY_search_console!A:C,3,0) -> 316 | J28: =IF(I28>0,(H28-I28)/I28,"N/A") -> -0.98417722

Sheet Top Keyword Rankings
A1: Map ID | B1: Page Title | C1: URL | D1: Top Keyword 1 | E1: Position 1 | F1: Volume 1 | G1: Top Keyword 2 | H1: Position 2 | I1: Volume 2 | J1: Top Keyword 3 | K1: Position 3 | L1: Volume 3
A2: 1 | B2: Attorney Hub | C2: https://sbrownlawyer.com/attorneys/ | D2: =IFERROR(__xludf.DUMMYFUNCTION("IFERROR(INDEX(SORT(FILTER(semrush_keywords!A:D, semrush_keywords!D:D=$C2), 2, 1), 1, 1), """")"),"mary e samaan attorney photos") -> mary e samaan attorney photos | E2: =IFERROR(__xludf.DUMMYFUNCTION("IFERROR(INDEX(SORT(FILTER(semrush_keywords!A:D, semrush_keywords!D:D=$C2), 2, 1), 1, 2), """")"),18.0) -> 18 | F2: =IFERROR(__xludf.DUMMYFUNCTION("IFERROR(INDEX(SORT(FILTER(semrush_keywords!A:D, semrush_keywords!D:D=$C2), 2, 1), 1, 3), """")"),40.0) -> 40 | G2: =IFERROR(__xludf.DUMMYFUNCTION("IFERROR(INDEX(SORT(FILTER(semrush_keywords!A:D, semrush_keywords!D:D=$C2), 2, 1), 2, 1), """")"),"lawyers in texas city tx") -> lawyers in texas city tx | H2: =IFERROR(__xludf.DUMMYFUNCTION("IFERROR(INDEX(SORT(FILTER(semrush_keywords!A:D, semrush_keywords!D:D=$C2), 2, 1), 2, 2), """")"),21.0) -> 21 | I2: =IFERROR(__xludf.DUMMYFUNCTION("IFERROR(INDEX(SORT(FILTER(semrush_keywords!A:D, semrush_keywords!D:D=$C2), 2, 1), 2, 3), """")"),90.0) -> 90 | J2: =IFERROR(__xludf.DUMMYFUNCTION("IFERROR(INDEX(SORT(FILTER(semrush_keywords!$A:$D, semrush_keywords!$D:$D=$C2), 2, 1), 3, 1), """")"),"scott and associates houston") -> scott and associates houston | K2: =IFERROR(__xludf.DUMMYFUNCTION("IFERROR(INDEX(SORT(FILTER(semrush_keywords!$A:$D, semrush_keywords!$D:$D=$C2), 2, 1), 3, 2), """")"),22.0) -> 22 | L2: =IFERROR(__xludf.DUMMYFUNCTION("IFERROR(INDEX(SORT(FILTER(semrush_keywords!$A:$D, semrush_keywords!$D:$D=$C2), 2, 1), 3, 3), """") "),40.0) -> 40
A3: 2 | B3: Location Hub | C3: https://sbrownlawyer.com/texas/locations/ | D3: =IFERROR(__xludf.DUMMYFUNCTION("IFERROR(INDEX(SORT(FILTER(semrush_keywords!A:D, semrush_keywords!D:D=$C3), 2, 1), 1, 1), """")"),"family law attorney angleton tx") -> family law attorney angleton tx | E3: =IFERROR(__xludf.DUMMYFUNCTION("IFERROR(INDEX(SORT(FILTER(semrush_keywords!A:D, semrush_keywords!D:D=$C3), 2, 1), 1, 2), """")"),27.0) -> 27 | F3: =IFERROR(__xludf.DUMMYFUNCTION("IFERROR(INDEX(SORT(FILTER(semrush_keywords!A:D, semrush_keywords!D:D=$C3), 2, 1), 1, 3), """")"),140.0) -> 140 | G3: =IFERROR(__xludf.DUMMYFUNCTION("IFERROR(INDEX(SORT(FILTER(semrush_keywords!A:D, semrush_keywords!D:D=$C3), 2, 1), 2, 1), """")"),"family law attorney angleton tx") -> family law attorney angleton tx | H3: =IFERROR(__xludf.DUMMYFUNCTION("IFERROR(INDEX(SORT(FILTER(semrush_keywords!A:D, semrush_keywords!D:D=$C3), 2, 1), 2, 2), """")"),61.0) -> 61 | I3: =IFERROR(__xludf.DUMMYFUNCTION("IFERROR(INDEX(SORT(FILTER(semrush_keywords!A:D, semrush_keywords!D:D=$C3), 2, 1), 2, 3), """")"),140.0) -> 140 | J3: =IFERROR(__xludf.DUMMYFUNCTION("IFERROR(INDEX(SORT(FILTER(semrush_keywords!$A:$D, semrush_keywords!$D:$D=$C3), 2, 1), 3, 1), """")"),"family attorney angleton") -> family attorney angleton | K3: =IFERROR(__xludf.DUMMYFUNCTION("IFERROR(INDEX(SORT(FILTER(semrush_keywords!$A:$D, semrush_keywords!$D:$D=$C3), 2, 1), 3, 2), """")"),74.0) -> 74 | L3: =IFERROR(__xludf.DUMMYFUNCTION("IFERROR(INDEX(SORT(FILTER(semrush_keywords!$A:$D, semrush_keywords!$D:$D=$C3), 2, 1), 3, 3), """") "),70.0) -> 70
A4: 3 | B4: Divorce Hub | C4: https://sbrownlawyer.com/divorce/ | D4: =IFERROR(__xludf.DUMMYFUNCTION("IFERROR(INDEX(SORT(FILTER(semrush_keywords!A:D, semrush_keywords!D:D=$C4), 2, 1), 1, 1), """")"),"attorneys in brazoria county texas") -> attorneys in brazoria county texas | E4: =IFERROR(__xludf.DUMMYFUNCTION("IFERROR(INDEX(SORT(FILTER(semrush_keywords!A:D, semrush_keywords!D:D=$C4), 2, 1), 1, 2), """")"),15.0) -> 15 | F4: =IFERROR(__xludf.DUMMYFUNCTION("IFERROR(INDEX(SORT(FILTER(semrush_keywords!A:D, semrush_keywords!D:D=$C4), 2, 1), 1, 3), """")"),110.0) -> 110 | G4: =IFERROR(__xludf.DUMMYFUNCTION("IFERROR(INDEX(SORT(FILTER(semrush_keywords!A:D, semrush_keywords!D:D=$C4), 2, 1), 2, 1), """")"),"lawyers in brazoria county tx") -> lawyers in brazoria county tx | H4: =IFERROR(__xludf.DUMMYFUNCTION("IFERROR(INDEX(SORT(FILTER(semrush_keywords!A:D, semrush_keywords!D:D=$C4), 2, 1), 2, 2), """")"),20.0) -> 20 | I4: =IFERROR(__xludf.DUMMYFUNCTION("IFERROR(INDEX(SORT(FILTER(semrush_keywords!A:D, semrush_keywords!D:D=$C4), 2, 1), 2, 3), """")"),140.0) -> 140 | J4: =IFERROR(__xludf.DUMMYFUNCTION("IFERROR(INDEX(SORT(FILTER(semrush_keywords!$A:$D, semrush_keywords!$D:$D=$C4), 2, 1), 3, 1), """")"),"divorce attorney angleton") -> divorce attorney angleton | K4: =IFERROR(__xludf.DUMMYFUNCTION("IFERROR(INDEX(SORT(FILTER(semrush_keywords!$A:$D, semrush_keywords!$D:$D=$C4), 2, 1), 3, 2), """")"),22.0) -> 22 | L4: =IFERROR(__xludf.DUMMYFUNCTION("IFERROR(INDEX(SORT(FILTER(semrush_keywords!$A:$D, semrush_keywords!$D:$D=$C4), 2, 1), 3, 3), """") "),170.0) -> 170
A5: 4 | B5: Child Custody Hub | C5: https://sbrownlawyer.com/child-custody/ | D5: =IFERROR(__xludf.DUMMYFUNCTION("IFERROR(INDEX(SORT(FILTER(semrush_keywords!A:D, semrush_keywords!D:D=$C5), 2, 1), 1, 1), """")"),"child custody lawyer texas") -> child custody lawyer texas | E5: =IFERROR(__xludf.DUMMYFUNCTION("IFERROR(INDEX(SORT(FILTER(semrush_keywords!A:D, semrush_keywords!D:D=$C5), 2, 1), 1, 2), """")"),22.0) -> 22 | F5: =IFERROR(__xludf.DUMMYFUNCTION("IFERROR(INDEX(SORT(FILTER(semrush_keywords!A:D, semrush_keywords!D:D=$C5), 2, 1), 1, 3), """")"),110.0) -> 110 | G5: =IFERROR(__xludf.DUMMYFUNCTION("IFERROR(INDEX(SORT(FILTER(semrush_keywords!A:D, semrush_keywords!D:D=$C5), 2, 1), 2, 1), """")"),"texas parental rights lawyer") -> texas parental rights lawyer | H5: =IFERROR(__xludf.DUMMYFUNCTION("IFERROR(INDEX(SORT(FILTER(semrush_keywords!A:D, semrush_keywords!D:D=$C5), 2, 1), 2, 2), """")"),23.0) -> 23 | I5: =IFERROR(__xludf.DUMMYFUNCTION("IFERROR(INDEX(SORT(FILTER(semrush_keywords!A:D, semrush_keywords!D:D=$C5), 2, 1), 2, 3), """")"),70.0) -> 70 | J5: =IFERROR(__xludf.DUMMYFUNCTION("IFERROR(INDEX(SORT(FILTER(semrush_keywords!$A:$D, semrush_keywords!$D:$D=$C5), 2, 1), 3, 1), """")"),"texas child custody lawyers") -> texas child custody lawyers | K5: =IFERROR(__xludf.DUMMYFUNCTION("IFERROR(INDEX(SORT(FILTER(semrush_keywords!$A:$D, semrush_keywords!$D:$D=$C5), 2, 1), 3, 2), """")"),28.0) -> 28 | L5: =IFERROR(__xludf.DUMMYFUNCTION("IFERROR(INDEX(SORT(FILTER(semrush_keywords!$A:$D, semrush_keywords!$D:$D=$C5), 2, 1), 3, 3), """") "),110.0) -> 110
A6: 5 | B6: Child Support Hub | C6: https://sbrownlawyer.com/child-support/ | D6: =IFERROR(__xludf.DUMMYFUNCTION("IFERROR(INDEX(SORT(FILTER(semrush_keywords!A:D, semrush_keywords!D:D=$C6), 2, 1), 1, 1), """")"),"angleton child support attorney") -> angleton child support attorney | E6: =IFERROR(__xludf.DUMMYFUNCTION("IFERROR(INDEX(SORT(FILTER(semrush_keywords!A:D, semrush_keywords!D:D=$C6), 2, 1), 1, 2), """")"),29.0) -> 29 | F6: =IFERROR(__xludf.DUMMYFUNCTION("IFERROR(INDEX(SORT(FILTER(semrush_keywords!A:D, semrush_keywords!D:D=$C6), 2, 1), 1, 3), """")"),50.0) -> 50 | G6: =IFERROR(__xludf.DUMMYFUNCTION("IFERROR(INDEX(SORT(FILTER(semrush_keywords!A:D, semrush_keywords!D:D=$C6), 2, 1), 2, 1), """")"),"texas child support attorney") -> texas child support attorney | H6: =IFERROR(__xludf.DUMMYFUNCTION("IFERROR(INDEX(SORT(FILTER(semrush_keywords!A:D, semrush_keywords!D:D=$C6), 2, 1), 2, 2), """")"),49.0) -> 49 | I6: =IFERROR(__xludf.DUMMYFUNCTION("IFERROR(INDEX(SORT(FILTER(semrush_keywords!A:D, semrush_keywords!D:D=$C6), 2, 1), 2, 3), """")"),70.0) -> 70 | J6: =IFERROR(__xludf.DUMMYFUNCTION("IFERROR(INDEX(SORT(FILTER(semrush_keywords!$A:$D, semrush_keywords!$D:$D=$C6), 2, 1), 3, 1), """")"),"houston child support attorneys") -> houston child support attorneys | K6: =IFERROR(__xludf.DUMMYFUNCTION("IFERROR(INDEX(SORT(FILTER(semrush_keywords!$A:$D, semrush_keywords!$D:$D=$C6), 2, 1), 3, 2), """")"),68.0) -> 68 | L6: =IFERROR(__xludf.DUMMYFUNCTION("IFERROR(INDEX(SORT(FILTER(semrush_keywords!$A:$D, semrush_keywords!$D:$D=$C6), 2, 1), 3, 3), """") "),70.0) -> 70
A7: 6 | B7: Spousal Support / Alimony Hub | C7: https://sbrownlawyer.com/attorneys-working-to-achieve-your-alimony-goals/ | D7: =IFERROR(__xludf.DUMMYFUNCTION("IFERROR(INDEX(SORT(FILTER(semrush_keywords!A:D, semrush_keywords!D:D=$C7), 2, 1), 1, 1), """")"),"") | E7: =IFERROR(__xludf.DUMMYFUNCTION("IFERROR(INDEX(SORT(FILTER(semrush_keywords!A:D, semrush_keywords!D:D=$C7), 2, 1), 1, 2), """")"),"") | F7: =IFERROR(__xludf.DUMMYFUNCTION("IFERROR(INDEX(SORT(FILTER(semrush_keywords!A:D, semrush_keywords!D:D=$C7), 2, 1), 1, 3), """")"),"") | G7: =IFERROR(__xludf.DUMMYFUNCTION("IFERROR(INDEX(SORT(FILTER(semrush_keywords!A:D, semrush_keywords!D:D=$C7), 2, 1), 2, 1), """")"),"") | H7: =IFERROR(__xludf.DUMMYFUNCTION("IFERROR(INDEX(SORT(FILTER(semrush_keywords!A:D, semrush_keywords!D:D=$C7), 2, 1), 2, 2), """")"),"") | I7: =IFERROR(__xludf.DUMMYFUNCTION("IFERROR(INDEX(SORT(FILTER(semrush_keywords!A:D, semrush_keywords!D:D=$C7), 2, 1), 2, 3), """")"),"") | J7: =IFERROR(__xludf.DUMMYFUNCTION("IFERROR(INDEX(SORT(FILTER(semrush_keywords!$A:$D, semrush_keywords!$D:$D=$C7), 2, 1), 3, 1), """")"),"") | K7: =IFERROR(__xludf.DUMMYFUNCTION("IFERROR(INDEX(SORT(FILTER(semrush_keywords!$A:$D, semrush_keywords!$D:$D=$C7), 2, 1), 3, 2), """")"),"") | L7: =IFERROR(__xludf.DUMMYFUNCTION("IFERROR(INDEX(SORT(FILTER(semrush_keywords!$A:$D, semrush_keywords!$D:$D=$C7), 2, 1), 3, 3), """") "),"")
A8: 7 | B8: Property Division Hub | C8: https://sbrownlawyer.com/division-of-property/ | D8: =IFERROR(__xludf.DUMMYFUNCTION("IFERROR(INDEX(SORT(FILTER(semrush_keywords!A:D, semrush_keywords!D:D=$C8), 2, 1), 1, 1), """")"),"foreclosures in brazoria county texas") -> foreclosures in brazoria county texas | E8: =IFERROR(__xludf.DUMMYFUNCTION("IFERROR(INDEX(SORT(FILTER(semrush_keywords!A:D, semrush_keywords!D:D=$C8), 2, 1), 1, 2), """")"),79.0) -> 79 | F8: =IFERROR(__xludf.DUMMYFUNCTION("IFERROR(INDEX(SORT(FILTER(semrush_keywords!A:D, semrush_keywords!D:D=$C8), 2, 1), 1, 3), """")"),40.0) -> 40 | G8: =IFERROR(__xludf.DUMMYFUNCTION("IFERROR(INDEX(SORT(FILTER(semrush_keywords!A:D, semrush_keywords!D:D=$C8), 2, 1), 2, 1), """")"),"property division attorney the woodlands") -> property division attorney the woodlands | H8: =IFERROR(__xludf.DUMMYFUNCTION("IFERROR(INDEX(SORT(FILTER(semrush_keywords!A:D, semrush_keywords!D:D=$C8), 2, 1), 2, 2), """")"),79.0) -> 79 | I8: =IFERROR(__xludf.DUMMYFUNCTION("IFERROR(INDEX(SORT(FILTER(semrush_keywords!A:D, semrush_keywords!D:D=$C8), 2, 1), 2, 3), """")"),50.0) -> 50 | J8: =IFERROR(__xludf.DUMMYFUNCTION("IFERROR(INDEX(SORT(FILTER(semrush_keywords!$A:$D, semrush_keywords!$D:$D=$C8), 2, 1), 3, 1), """")"),"lawyers in brazoria county") -> lawyers in brazoria county | K8: =IFERROR(__xludf.DUMMYFUNCTION("IFERROR(INDEX(SORT(FILTER(semrush_keywords!$A:$D, semrush_keywords!$D:$D=$C8), 2, 1), 3, 2), """")"),81.0) -> 81 | L8: =IFERROR(__xludf.DUMMYFUNCTION("IFERROR(INDEX(SORT(FILTER(semrush_keywords!$A:$D, semrush_keywords!$D:$D=$C8), 2, 1), 3, 3), """") "),50.0) -> 50
A9: 8 | B9: Paternity Hub | C9: https://sbrownlawyer.com/paternity/ | D9: =IFERROR(__xludf.DUMMYFUNCTION("IFERROR(INDEX(SORT(FILTER(semrush_keywords!A:D, semrush_keywords!D:D=$C9), 2, 1), 1, 1), """")"),"") | E9: =IFERROR(__xludf.DUMMYFUNCTION("IFERROR(INDEX(SORT(FILTER(semrush_keywords!A:D, semrush_keywords!D:D=$C9), 2, 1), 1, 2), """")"),"") | F9: =IFERROR(__xludf.DUMMYFUNCTION("IFERROR(INDEX(SORT(FILTER(semrush_keywords!A:D, semrush_keywords!D:D=$C9), 2, 1), 1, 3), """")"),"") | G9: =IFERROR(__xludf.DUMMYFUNCTION("IFERROR(INDEX(SORT(FILTER(semrush_keywords!A:D, semrush_keywords!D:D=$C9), 2, 1), 2, 1), """")"),"") | H9: =IFERROR(__xludf.DUMMYFUNCTION("IFERROR(INDEX(SORT(FILTER(semrush_keywords!A:D, semrush_keywords!D:D=$C9), 2, 1), 2, 2), """")"),"") | I9: =IFERROR(__xludf.DUMMYFUNCTION("IFERROR(INDEX(SORT(FILTER(semrush_keywords!A:D, semrush_keywords!D:D=$C9), 2, 1), 2, 3), """")"),"") | J9: =IFERROR(__xludf.DUMMYFUNCTION("IFERROR(INDEX(SORT(FILTER(semrush_keywords!$A:$D, semrush_keywords!$D:$D=$C9), 2, 1), 3, 1), """")"),"") | K9: =IFERROR(__xludf.DUMMYFUNCTION("IFERROR(INDEX(SORT(FILTER(semrush_keywords!$A:$D, semrush_keywords!$D:$D=$C9), 2, 1), 3, 2), """")"),"") | L9: =IFERROR(__xludf.DUMMYFUNCTION("IFERROR(INDEX(SORT(FILTER(semrush_keywords!$A:$D, semrush_keywords!$D:$D=$C9), 2, 1), 3, 3), """") "),"")
A10: 10 | B10: Contested Divorce | C10: https://sbrownlawyer.com/complex-and-contested-divorce-attorneys/ | D10: =IFERROR(__xludf.DUMMYFUNCTION("IFERROR(INDEX(SORT(FILTER(semrush_keywords!A:D, semrush_keywords!D:D=$C10), 2, 1), 1, 1), """")"),"contested divorce attorneys in houston tx") -> contested divorce attorneys in houston tx | E10: =IFERROR(__xludf.DUMMYFUNCTION("IFERROR(INDEX(SORT(FILTER(semrush_keywords!A:D, semrush_keywords!D:D=$C10), 2, 1), 1, 2), """")"),40.0) -> 40 | F10: =IFERROR(__xludf.DUMMYFUNCTION("IFERROR(INDEX(SORT(FILTER(semrush_keywords!A:D, semrush_keywords!D:D=$C10), 2, 1), 1, 3), """")"),70.0) -> 70 | G10: =IFERROR(__xludf.DUMMYFUNCTION("IFERROR(INDEX(SORT(FILTER(semrush_keywords!A:D, semrush_keywords!D:D=$C10), 2, 1), 2, 1), """")"),"contested divorce lawyers in houston tx") -> contested divorce lawyers in houston tx | H10: =IFERROR(__xludf.DUMMYFUNCTION("IFERROR(INDEX(SORT(FILTER(semrush_keywords!A:D, semrush_keywords!D:D=$C10), 2, 1), 2, 2), """")"),42.0) -> 42 | I10: =IFERROR(__xludf.DUMMYFUNCTION("IFERROR(INDEX(SORT(FILTER(semrush_keywords!A:D, semrush_keywords!D:D=$C10), 2, 1), 2, 3), """")"),50.0) -> 50 | J10: =IFERROR(__xludf.DUMMYFUNCTION("IFERROR(INDEX(SORT(FILTER(semrush_keywords!$A:$D, semrush_keywords!$D:$D=$C10), 2, 1), 3, 1), """")"),"") | K10: =IFERROR(__xludf.DUMMYFUNCTION("IFERROR(INDEX(SORT(FILTER(semrush_keywords!$A:$D, semrush_keywords!$D:$D=$C10), 2, 1), 3, 2), """")"),"") | L10: =IFERROR(__xludf.DUMMYFUNCTION("IFERROR(INDEX(SORT(FILTER(semrush_keywords!$A:$D, semrush_keywords!$D:$D=$C10), 2, 1), 3, 3), """") "),"")
A11: 11 | B11: Uncontested Divorce | C11: https://sbrownlawyer.com/uncontested-divorce-lawyer-in-pearland/ | D11: =IFERROR(__xludf.DUMMYFUNCTION("IFERROR(INDEX(SORT(FILTER(semrush_keywords!A:D, semrush_keywords!D:D=$C11), 2, 1), 1, 1), """")"),"divorce lawyers in pearland tx") -> divorce lawyers in pearland tx | E11: =IFERROR(__xludf.DUMMYFUNCTION("IFERROR(INDEX(SORT(FILTER(semrush_keywords!A:D, semrush_keywords!D:D=$C11), 2, 1), 1, 2), """")"),37.0) -> 37 | F11: =IFERROR(__xludf.DUMMYFUNCTION("IFERROR(INDEX(SORT(FILTER(semrush_keywords!A:D, semrush_keywords!D:D=$C11), 2, 1), 1, 3), """")"),50.0) -> 50 | G11: =IFERROR(__xludf.DUMMYFUNCTION("IFERROR(INDEX(SORT(FILTER(semrush_keywords!A:D, semrush_keywords!D:D=$C11), 2, 1), 2, 1), """")"),"divorce lawyers pearland") -> divorce lawyers pearland | H11: =IFERROR(__xludf.DUMMYFUNCTION("IFERROR(INDEX(SORT(FILTER(semrush_keywords!A:D, semrush_keywords!D:D=$C11), 2, 1), 2, 2), """")"),40.0) -> 40 | I11: =IFERROR(__xludf.DUMMYFUNCTION("IFERROR(INDEX(SORT(FILTER(semrush_keywords!A:D, semrush_keywords!D:D=$C11), 2, 1), 2, 3), """")"),170.0) -> 170 | J11: =IFERROR(__xludf.DUMMYFUNCTION("IFERROR(INDEX(SORT(FILTER(semrush_keywords!$A:$D, semrush_keywords!$D:$D=$C11), 2, 1), 3, 1), """")"),"divorce law firm pearland") -> divorce law firm pearland | K11: =IFERROR(__xludf.DUMMYFUNCTION("IFERROR(INDEX(SORT(FILTER(semrush_keywords!$A:$D, semrush_keywords!$D:$D=$C11), 2, 1), 3, 2), """")"),47.0) -> 47 | L11: =IFERROR(__xludf.DUMMYFUNCTION("IFERROR(INDEX(SORT(FILTER(semrush_keywords!$A:$D, semrush_keywords!$D:$D=$C11), 2, 1), 3, 3), """") "),40.0) -> 40
A12: 12 | B12: Child Custody Modification | C12: https://sbrownlawyer.com/modification-of-custody/ | D12: =IFERROR(__xludf.DUMMYFUNCTION("IFERROR(INDEX(SORT(FILTER(semrush_keywords!A:D, semrush_keywords!D:D=$C12), 2, 1), 1, 1), """")"),"angleton child custody lawyer") -> angleton child custody lawyer | E12: =IFERROR(__xludf.DUMMYFUNCTION("IFERROR(INDEX(SORT(FILTER(semrush_keywords!A:D, semrush_keywords!D:D=$C12), 2, 1), 1, 2), """")"),27.0) -> 27 | F12: =IFERROR(__xludf.DUMMYFUNCTION("IFERROR(INDEX(SORT(FILTER(semrush_keywords!A:D, semrush_keywords!D:D=$C12), 2, 1), 1, 3), """")"),70.0) -> 70 | G12: =IFERROR(__xludf.DUMMYFUNCTION("IFERROR(INDEX(SORT(FILTER(semrush_keywords!A:D, semrush_keywords!D:D=$C12), 2, 1), 2, 1), """")"),"child custody attorney angleton") -> child custody attorney angleton | H12: =IFERROR(__xludf.DUMMYFUNCTION("IFERROR(INDEX(SORT(FILTER(semrush_keywords!A:D, semrush_keywords!D:D=$C12), 2, 1), 2, 2), """")"),48.0) -> 48 | I12: =IFERROR(__xludf.DUMMYFUNCTION("IFERROR(INDEX(SORT(FILTER(semrush_keywords!A:D, semrush_keywords!D:D=$C12), 2, 1), 2, 3), """")"),50.0) -> 50 | J12: =IFERROR(__xludf.DUMMYFUNCTION("IFERROR(INDEX(SORT(FILTER(semrush_keywords!$A:$D, semrush_keywords!$D:$D=$C12), 2, 1), 3, 1), """")"),"angleton child custody attorney") -> angleton child custody attorney | K12: =IFERROR(__xludf.DUMMYFUNCTION("IFERROR(INDEX(SORT(FILTER(semrush_keywords!$A:$D, semrush_keywords!$D:$D=$C12), 2, 1), 3, 2), """")"),53.0) -> 53 | L12: =IFERROR(__xludf.DUMMYFUNCTION("IFERROR(INDEX(SORT(FILTER(semrush_keywords!$A:$D, semrush_keywords!$D:$D=$C12), 2, 1), 3, 3), """") "),50.0) -> 50
A13: 13 | B13: Child Support Modification | C13: https://sbrownlawyer.com/child-support-modifications/ | D13: =IFERROR(__xludf.DUMMYFUNCTION("IFERROR(INDEX(SORT(FILTER(semrush_keywords!A:D, semrush_keywords!D:D=$C13), 2, 1), 1, 1), """")"),"") | E13: =IFERROR(__xludf.DUMMYFUNCTION("IFERROR(INDEX(SORT(FILTER(semrush_keywords!A:D, semrush_keywords!D:D=$C13), 2, 1), 1, 2), """")"),"") | F13: =IFERROR(__xludf.DUMMYFUNCTION("IFERROR(INDEX(SORT(FILTER(semrush_keywords!A:D, semrush_keywords!D:D=$C13), 2, 1), 1, 3), """")"),"") | G13: =IFERROR(__xludf.DUMMYFUNCTION("IFERROR(INDEX(SORT(FILTER(semrush_keywords!A:D, semrush_keywords!D:D=$C13), 2, 1), 2, 1), """")"),"") | H13: =IFERROR(__xludf.DUMMYFUNCTION("IFERROR(INDEX(SORT(FILTER(semrush_keywords!A:D, semrush_keywords!D:D=$C13), 2, 1), 2, 2), """")"),"") | I13: =IFERROR(__xludf.DUMMYFUNCTION("IFERROR(INDEX(SORT(FILTER(semrush_keywords!A:D, semrush_keywords!D:D=$C13), 2, 1), 2, 3), """")"),"") | J13: =IFERROR(__xludf.DUMMYFUNCTION("IFERROR(INDEX(SORT(FILTER(semrush_keywords!$A:$D, semrush_keywords!$D:$D=$C13), 2, 1), 3, 1), """")"),"") | K13: =IFERROR(__xludf.DUMMYFUNCTION("IFERROR(INDEX(SORT(FILTER(semrush_keywords!$A:$D, semrush_keywords!$D:$D=$C13), 2, 1), 3, 2), """")"),"") | L13: =IFERROR(__xludf.DUMMYFUNCTION("IFERROR(INDEX(SORT(FILTER(semrush_keywords!$A:$D, semrush_keywords!$D:$D=$C13), 2, 1), 3, 3), """") "),"")
A14: 14 | B14: Child Support Enforcement | C14: https://sbrownlawyer.com/enforcing-child-support-orders/ | D14: =IFERROR(__xludf.DUMMYFUNCTION("IFERROR(INDEX(SORT(FILTER(semrush_keywords!A:D, semrush_keywords!D:D=$C14), 2, 1), 1, 1), """")"),"") | E14: =IFERROR(__xludf.DUMMYFUNCTION("IFERROR(INDEX(SORT(FILTER(semrush_keywords!A:D, semrush_keywords!D:D=$C14), 2, 1), 1, 2), """")"),"") | F14: =IFERROR(__xludf.DUMMYFUNCTION("IFERROR(INDEX(SORT(FILTER(semrush_keywords!A:D, semrush_keywords!D:D=$C14), 2, 1), 1, 3), """")"),"") | G14: =IFERROR(__xludf.DUMMYFUNCTION("IFERROR(INDEX(SORT(FILTER(semrush_keywords!A:D, semrush_keywords!D:D=$C14), 2, 1), 2, 1), """")"),"") | H14: =IFERROR(__xludf.DUMMYFUNCTION("IFERROR(INDEX(SORT(FILTER(semrush_keywords!A:D, semrush_keywords!D:D=$C14), 2, 1), 2, 2), """")"),"") | I14: =IFERROR(__xludf.DUMMYFUNCTION("IFERROR(INDEX(SORT(FILTER(semrush_keywords!A:D, semrush_keywords!D:D=$C14), 2, 1), 2, 3), """")"),"") | J14: =IFERROR(__xludf.DUMMYFUNCTION("IFERROR(INDEX(SORT(FILTER(semrush_keywords!$A:$D, semrush_keywords!$D:$D=$C14), 2, 1), 3, 1), """")"),"") | K14: =IFERROR(__xludf.DUMMYFUNCTION("IFERROR(INDEX(SORT(FILTER(semrush_keywords!$A:$D, semrush_keywords!$D:$D=$C14), 2, 1), 3, 2), """")"),"") | L14: =IFERROR(__xludf.DUMMYFUNCTION("IFERROR(INDEX(SORT(FILTER(semrush_keywords!$A:$D, semrush_keywords!$D:$D=$C14), 2, 1), 3, 3), """") "),"")
A15: 15 | B15: Parenting Plans | C15: https://sbrownlawyer.com/creative-custody-agreements/ | D15: =IFERROR(__xludf.DUMMYFUNCTION("IFERROR(INDEX(SORT(FILTER(semrush_keywords!A:D, semrush_keywords!D:D=$C15), 2, 1), 1, 1), """")"),"") | E15: =IFERROR(__xludf.DUMMYFUNCTION("IFERROR(INDEX(SORT(FILTER(semrush_keywords!A:D, semrush_keywords!D:D=$C15), 2, 1), 1, 2), """")"),"") | F15: =IFERROR(__xludf.DUMMYFUNCTION("IFERROR(INDEX(SORT(FILTER(semrush_keywords!A:D, semrush_keywords!D:D=$C15), 2, 1), 1, 3), """")"),"") | G15: =IFERROR(__xludf.DUMMYFUNCTION("IFERROR(INDEX(SORT(FILTER(semrush_keywords!A:D, semrush_keywords!D:D=$C15), 2, 1), 2, 1), """")"),"") | H15: =IFERROR(__xludf.DUMMYFUNCTION("IFERROR(INDEX(SORT(FILTER(semrush_keywords!A:D, semrush_keywords!D:D=$C15), 2, 1), 2, 2), """")"),"") | I15: =IFERROR(__xludf.DUMMYFUNCTION("IFERROR(INDEX(SORT(FILTER(semrush_keywords!A:D, semrush_keywords!D:D=$C15), 2, 1), 2, 3), """")"),"") | J15: =IFERROR(__xludf.DUMMYFUNCTION("IFERROR(INDEX(SORT(FILTER(semrush_keywords!$A:$D, semrush_keywords!$D:$D=$C15), 2, 1), 3, 1), """")"),"") | K15: =IFERROR(__xludf.DUMMYFUNCTION("IFERROR(INDEX(SORT(FILTER(semrush_keywords!$A:$D, semrush_keywords!$D:$D=$C15), 2, 1), 3, 2), """")"),"") | L15: =IFERROR(__xludf.DUMMYFUNCTION("IFERROR(INDEX(SORT(FILTER(semrush_keywords!$A:$D, semrush_keywords!$D:$D=$C15), 2, 1), 3, 3), """") "),"")
A16: 17 | B16: Equitable Distribution | C16: https://sbrownlawyer.com/how-is-community-property-divided/ | D16: =IFERROR(__xludf.DUMMYFUNCTION("IFERROR(INDEX(SORT(FILTER(semrush_keywords!A:D, semrush_keywords!D:D=$C16), 2, 1), 1, 1), """")"),"") | E16: =IFERROR(__xludf.DUMMYFUNCTION("IFERROR(INDEX(SORT(FILTER(semrush_keywords!A:D, semrush_keywords!D:D=$C16), 2, 1), 1, 2), """")"),"") | F16: =IFERROR(__xludf.DUMMYFUNCTION("IFERROR(INDEX(SORT(FILTER(semrush_keywords!A:D, semrush_keywords!D:D=$C16), 2, 1), 1, 3), """")"),"") | G16: =IFERROR(__xludf.DUMMYFUNCTION("IFERROR(INDEX(SORT(FILTER(semrush_keywords!A:D, semrush_keywords!D:D=$C16), 2, 1), 2, 1), """")"),"") | H16: =IFERROR(__xludf.DUMMYFUNCTION("IFERROR(INDEX(SORT(FILTER(semrush_keywords!A:D, semrush_keywords!D:D=$C16), 2, 1), 2, 2), """")"),"") | I16: =IFERROR(__xludf.DUMMYFUNCTION("IFERROR(INDEX(SORT(FILTER(semrush_keywords!A:D, semrush_keywords!D:D=$C16), 2, 1), 2, 3), """")"),"") | J16: =IFERROR(__xludf.DUMMYFUNCTION("IFERROR(INDEX(SORT(FILTER(semrush_keywords!$A:$D, semrush_keywords!$D:$D=$C16), 2, 1), 3, 1), """")"),"") | K16: =IFERROR(__xludf.DUMMYFUNCTION("IFERROR(INDEX(SORT(FILTER(semrush_keywords!$A:$D, semrush_keywords!$D:$D=$C16), 2, 1), 3, 2), """")"),"") | L16: =IFERROR(__xludf.DUMMYFUNCTION("IFERROR(INDEX(SORT(FILTER(semrush_keywords!$A:$D, semrush_keywords!$D:$D=$C16), 2, 1), 3, 3), """") "),"")
A17: 18 | B17: Establishing Paternity | C17: https://sbrownlawyer.com/paternity-attorney/ | D17: =IFERROR(__xludf.DUMMYFUNCTION("IFERROR(INDEX(SORT(FILTER(semrush_keywords!A:D, semrush_keywords!D:D=$C17), 2, 1), 1, 1), """")"),"paternity law firm the woodlands") -> paternity law firm the woodlands | E17: =IFERROR(__xludf.DUMMYFUNCTION("IFERROR(INDEX(SORT(FILTER(semrush_keywords!A:D, semrush_keywords!D:D=$C17), 2, 1), 1, 2), """")"),78.0) -> 78 | F17: =IFERROR(__xludf.DUMMYFUNCTION("IFERROR(INDEX(SORT(FILTER(semrush_keywords!A:D, semrush_keywords!D:D=$C17), 2, 1), 1, 3), """")"),50.0) -> 50 | G17: =IFERROR(__xludf.DUMMYFUNCTION("IFERROR(INDEX(SORT(FILTER(semrush_keywords!A:D, semrush_keywords!D:D=$C17), 2, 1), 2, 1), """")"),"paternity issues attorneys the woodlands") -> paternity issues attorneys the woodlands | H17: =IFERROR(__xludf.DUMMYFUNCTION("IFERROR(INDEX(SORT(FILTER(semrush_keywords!A:D, semrush_keywords!D:D=$C17), 2, 1), 2, 2), """")"),80.0) -> 80 | I17: =IFERROR(__xludf.DUMMYFUNCTION("IFERROR(INDEX(SORT(FILTER(semrush_keywords!A:D, semrush_keywords!D:D=$C17), 2, 1), 2, 3), """")"),50.0) -> 50 | J17: =IFERROR(__xludf.DUMMYFUNCTION("IFERROR(INDEX(SORT(FILTER(semrush_keywords!$A:$D, semrush_keywords!$D:$D=$C17), 2, 1), 3, 1), """")"),"pearland family lawyers") -> pearland family lawyers | K17: =IFERROR(__xludf.DUMMYFUNCTION("IFERROR(INDEX(SORT(FILTER(semrush_keywords!$A:$D, semrush_keywords!$D:$D=$C17), 2, 1), 3, 2), """")"),84.0) -> 84 | L17: =IFERROR(__xludf.DUMMYFUNCTION("IFERROR(INDEX(SORT(FILTER(semrush_keywords!$A:$D, semrush_keywords!$D:$D=$C17), 2, 1), 3, 3), """") "),70.0) -> 70
A18: 19 | B18: Emergency Custody Orders | C18: https://sbrownlawyer.com/child-custody/emergency/ | D18: =IFERROR(__xludf.DUMMYFUNCTION("IFERROR(INDEX(SORT(FILTER(semrush_keywords!A:D, semrush_keywords!D:D=$C18), 2, 1), 1, 1), """")"),"emergency custody attorney") -> emergency custody attorney | E18: =IFERROR(__xludf.DUMMYFUNCTION("IFERROR(INDEX(SORT(FILTER(semrush_keywords!A:D, semrush_keywords!D:D=$C18), 2, 1), 1, 2), """")"),33.0) -> 33 | F18: =IFERROR(__xludf.DUMMYFUNCTION("IFERROR(INDEX(SORT(FILTER(semrush_keywords!A:D, semrush_keywords!D:D=$C18), 2, 1), 1, 3), """")"),70.0) -> 70 | G18: =IFERROR(__xludf.DUMMYFUNCTION("IFERROR(INDEX(SORT(FILTER(semrush_keywords!A:D, semrush_keywords!D:D=$C18), 2, 1), 2, 1), """")"),"emergency custody lawyer") -> emergency custody lawyer | H18: =IFERROR(__xludf.DUMMYFUNCTION("IFERROR(INDEX(SORT(FILTER(semrush_keywords!A:D, semrush_keywords!D:D=$C18), 2, 1), 2, 2), """")"),43.0) -> 43 | I18: =IFERROR(__xludf.DUMMYFUNCTION("IFERROR(INDEX(SORT(FILTER(semrush_keywords!A:D, semrush_keywords!D:D=$C18), 2, 1), 2, 3), """")"),210.0) -> 210 | J18: =IFERROR(__xludf.DUMMYFUNCTION("IFERROR(INDEX(SORT(FILTER(semrush_keywords!$A:$D, semrush_keywords!$D:$D=$C18), 2, 1), 3, 1), """")"),"") | K18: =IFERROR(__xludf.DUMMYFUNCTION("IFERROR(INDEX(SORT(FILTER(semrush_keywords!$A:$D, semrush_keywords!$D:$D=$C18), 2, 1), 3, 2), """")"),"") | L18: =IFERROR(__xludf.DUMMYFUNCTION("IFERROR(INDEX(SORT(FILTER(semrush_keywords!$A:$D, semrush_keywords!$D:$D=$C18), 2, 1), 3, 3), """") "),"")
